<?xml version="1.0"?>
<robot xmlns:xacro="http://www.ros.org/wiki/xacro">

    <!-- Import Transmission -->
    <!-- Transmission macro -->
    <xacro:macro name="SimpleTransmissionPosition" params="joint n id">
    <transmission name="robot${id}/tran${n}">
        <type>transmission_interface/SimpleTransmission</type>
        <joint name="robot${id}/${joint}">
        <hardwareInterface>hardware_interface/PositionJointInterface</hardwareInterface>
        </joint>
        <actuator name="robot${id}/motor${n}">
        <mechanicalReduction>1</mechanicalReduction>
        </actuator>
    </transmission>
    </xacro:macro>
    <!-- Transmission macro -->
    <xacro:macro name="SimpleTransmissionEffort" params="joint n id">
    <transmission name="robot${id}/tran${n}">
        <type>transmission_interface/SimpleTransmission</type>
        <joint name="robot${id}/${joint}">
        <hardwareInterface>hardware_interface/EffortJointInterface</hardwareInterface>
        </joint>
        <actuator name="robot${id}/motor${n}">
        <mechanicalReduction>1</mechanicalReduction>
        </actuator>
    </transmission>
    </xacro:macro>
 
    <xacro:macro name="ur5_leader" params="id">
        <link name="robot${id}/base_link">
            <inertial>
                <origin xyz="-1.88052088812657E-05 -0.00215271082064172 0.0441443392060522" rpy="0 0 0" />
                <mass value="0.218376911489293" />
                <inertia ixx="0.000160297084827002" ixy="1.06759566549485E-08" ixz="-4.82637621739845E-08" iyy="0.000190111291063554" iyz="-5.70875681133123E-06" izz="9.3344618631843E-05"  />
            </inertial>
            <visual>
                <origin xyz="0 0 0" rpy="0 0 0" />
                <geometry>
                    <mesh filename="package://teleop_leaders/description/meshes/base_link.stl" />
                </geometry>
                <material name="">
                    <color rgba="0.752941176470588 0.752941176470588 0.752941176470588 1" />
                </material>
            </visual>
            <collision>
            <origin
                xyz="0 0 0" rpy="0 0 0" />
            <geometry>
                <mesh filename="package://teleop_leaders/description/meshes/base_link.stl" />
            </geometry>
            </collision>
        </link>
        <link name="robot${id}/link1">
            <inertial>
            <origin xyz="0.0148795119058397 -0.0192918546044606 -5.81797288082275E-07" rpy="0 0 0" />
            <mass value="0.041336" />
            <inertia ixx="7.1216E-06" ixy="-2.4776E-06" ixz="-1.4797E-10" iyy="1.2151E-05" iyz="7.5415E-11" izz="1.4757E-05" />
            </inertial>
            <visual>
            <origin xyz="0 0 0" rpy="0 0 0" />
            <geometry>
                <mesh filename="package://teleop_leaders/description/meshes/ur5/link1.stl" />
            </geometry>
            <material name="">
                <color rgba="0.79216 0.81961 0.93333 1" />
            </material>
            </visual>
            <collision>
            <origin xyz="0 0 0" rpy="0 0 0" />
            <geometry>
                <mesh filename="package://teleop_leaders/description/meshes/ur5/link1.stl" />
            </geometry>
            </collision>
        </link>
        <joint name="robot${id}/joint1" type="revolute">
            <origin xyz="-0.000125 0.0 0.099" rpy="-1.5707963267949 0 -1.5707963267949"/>
            <parent link="robot${id}/base_link" />
            <child link="robot${id}/link1" />
            <axis xyz="0 1 0" />
            <limit lower="-${pi}" upper="${pi}" effort="1" velocity="3.15" />
        </joint>
        <xacro:SimpleTransmissionEffort n="1" joint="joint1" id="${id}" />
        <xacro:SimpleTransmissionPosition n="1" joint="joint1" id="${id}" />

        <link name="robot${id}/link2">
            <inertial>
                <origin xyz="0.108251385472162 -1.58317230034011E-07 -0.0202158550740865" rpy="0 0 0" />
                <mass value="0.160618812979298" />
                <inertia ixx="1.76671350322107E-05" ixy="4.87568646451885E-10" ixz="-5.51581332832345E-09" iyy="0.000472063875264355" iyz="-1.98620293993225E-11" izz="0.000475235516433241" />
            </inertial>
            <visual>
                <origin xyz="0 0 0" rpy="0 0 0" />
                <geometry>
                    <mesh filename="package://teleop_leaders/description/meshes/ur5/link2.stl" />
                </geometry>
                <material name="">
                    <color rgba="0.792156862745098 0.819607843137255 0.933333333333333 1" />
                </material>
            </visual>
            <collision>
                <origin xyz="0 0 0" rpy="0 0 0" />
                <geometry>
                    <mesh filename="package://teleop_leaders/description/meshes/ur5/link2.stl" />
                </geometry>
            </collision>
        </link>
        <joint name="robot${id}/joint2" type="revolute">
            <origin xyz="0.0414999985951312 -0.0215795005865017 0" rpy="1.5707963267949 0 -1.5707963267949" />
            <parent link="robot${id}/link1" />
            <child link="robot${id}/link2" />
            <axis xyz="0 0 1" />
            <limit lower="-${pi}" upper="${pi}" effort="1" velocity="3.15" />
        </joint>
        SimpleTransmissionPosition
        <xacro:SimpleTransmissionEffort n="2" joint="joint2" id="${id}" />
        <xacro:SimpleTransmissionPosition n="2" joint="joint2" id="${id}" />

        <link name="robot${id}/link3">
            <inertial>
                <origin xyz="-0.0316552462456164 -9.12590103555044E-07 -0.0848518601257323" rpy="0 0 0" />
                <mass value="0.198785091752452" />
                <inertia ixx="0.000635320734986975" ixy="8.4703815473395E-12" ixz="-3.95444251161434E-05" iyy="0.000644635318996104" iyz="-1.13198040132376E-09" izz="3.89817699987472E-05"/>
            </inertial>
            <visual>
            <origin xyz="0 0 0" rpy="0 0 0" />
            <geometry>
                <mesh filename="package://teleop_leaders/description/meshes/ur5/link3.stl" />
            </geometry>
            <material name="">
                <color rgba="0.792156862745098 0.819607843137255 0.933333333333333 1" />
            </material>
            </visual>
            <collision>
            <origin xyz="0 0 0" rpy="0 0 0" />
            <geometry>
                <mesh filename="package://teleop_leaders/description/meshes/ur5/link3.stl" />
            </geometry>
            </collision>
        </link>
        <joint name="robot${id}/joint3" type="revolute">
            <origin xyz="0.216500001566666 0 0" rpy="3.14159238166912 1.5707963267949 0" />
            <parent link="robot${id}/link2" />
            <child link="robot${id}/link3" />
            <axis xyz="1 0 0" />
            <limit lower="-${pi}" upper="${pi}" effort="1" velocity="3.15" />
        </joint>
        <xacro:SimpleTransmissionEffort n="3" joint="joint3" id="${id}" />
        <xacro:SimpleTransmissionPosition n="3" joint="joint3" id="${id}" />

        <link name="robot${id}/link4">
            <inertial>
            <origin xyz="0 0 0" rpy="0 0 0" />
            <mass value="0.0355248600002842" />
            <inertia  ixx="4.47169794900115E-06" ixy="-1.20265785212545E-06" ixz="6.31952197550041E-11" iyy="6.92482483714141E-06" iyz="1.44458901552048E-11" izz="7.58542259681121E-06" />
            </inertial>
            <visual>
            <origin xyz="0 0 0" rpy="0 0 0" />
            <geometry>
                <mesh filename="package://teleop_leaders/description/meshes/ur5/link4.stl" />
            </geometry>
            <material name="">
                <color rgba="0.792156862745098 0.819607843137255 0.933333333333333 1" />
            </material>
            </visual>
            <collision>
            <origin xyz="0 0 0" rpy="0 0 0" />
            <geometry>
                <mesh filename="package://teleop_leaders/description/meshes/ur5/link4.stl" />
            </geometry>
            </collision>
        </link>
        <joint name="robot${id}/joint4" type="revolute">
            <origin xyz="0.003 0 -0.196500001566666" rpy="-1.5708 0 0" />
            <parent link="robot${id}/link3" />
            <child link="robot${id}/link4" />
            <axis xyz="1 0 0" />
            <limit lower="-${pi}" upper="${pi}" effort="1" velocity="3.15" />
        </joint>
        <xacro:SimpleTransmissionEffort n="4" joint="joint4" id="${id}" />
        <xacro:SimpleTransmissionPosition n="4" joint="joint4" id="${id}" />
        <link name="robot${id}/link5">
            <inertial>
            <origin xyz="0.0102587015573597 8.51173093480151E-07 -0.00137103417583417" rpy="0 0 0" />
            <mass value="0.0293815071396338" />
            <inertia ixx="3.57750484672151E-06" ixy="8.59800621237349E-11" ixz="-8.13508959894672E-07" iyy="5.51370306313873E-06" iyz="-8.45800360650432E-12" izz="5.1907065270068E-06" />
            </inertial>
            <visual>
            <origin xyz="0 0 0" rpy="0 0 0" />
            <geometry>
                <mesh filename="package://teleop_leaders/description/meshes/ur5/link5.stl" />
            </geometry>
            <material name="">
                <color rgba="0.79216 0.81961 0.93333 1" />
            </material>
            </visual>
            <collision>
            <origin xyz="0 0 0" rpy="0 0 0" />
            <geometry>
                <mesh filename="package://teleop_leaders/description/meshes/ur5/link5.stl" />
            </geometry>
            </collision>
        </link>
        <joint name="robot${id}/joint5" type="revolute">
            <origin xyz="0.017 -0.045 0.0" rpy="0 0 1.5707963267949" />
            <parent link="robot${id}/link4" />
            <child link="robot${id}/link5" />
            <axis xyz="1 0 0" />
            <limit lower="-${pi}" upper="${pi}" effort="1" velocity="3.15" />
        </joint>
        <xacro:SimpleTransmissionEffort n="5" joint="joint5" id="${id}" />
        <xacro:SimpleTransmissionPosition n="5" joint="joint5" id="${id}" />

        <link name="robot${id}/handle">
            <inertial>
            <origin xyz="-0.0269504648321372 -0.000444552753820911 0.00944823169908937" rpy="0 0 0" />
            <mass value="0.0792318961261061" />
            <inertia ixx="3.30813970525119E-05" ixy="1.1856468521745E-05" ixz="8.98678207145682E-07" iyy="3.49786415297126E-05" iyz="-5.09722128514016E-07" izz="5.60466661401102E-05" />
            </inertial>
            <visual>
            <origin xyz="0 0 0" rpy="0 0 0" />
            <geometry>
                <mesh filename="package://teleop_leaders/description/meshes/handle.stl" />
            </geometry>
            <material name="">
                <color rgba="0.792156862745098 0.819607843137255 0.933333333333333 1" />
            </material>
            </visual>
            <collision>
            <origin xyz="0.0 0 0" rpy="0 0 0" />
            <geometry>
                <mesh filename="package://teleop_leaders/description/meshes/handle.stl" />
            </geometry>
            </collision>
        </link>
        <joint name="robot${id}/joint6" type="revolute">
            <origin xyz="-0.001 0.0 0.015" rpy="0 0 0" />
            <parent link="robot${id}/link5" />
            <child link="robot${id}/handle" />
            <axis xyz="0.052336 0 0.99863" />
            <limit lower="-${pi}" upper="${pi}" effort="1" velocity="3.15" />
        </joint>
        <xacro:SimpleTransmissionEffort n="6" joint="joint6" id="${id}" />
        <xacro:SimpleTransmissionPosition n="6" joint="joint6" id="${id}" />

        <link name="robot${id}/trigger">
            <inertial>
            <origin xyz="0.0050484710643748 0.00657608716575382 0.0232192535585892" rpy="0 0 0" />
            <mass value="0.0113373798119285" />
            <inertia ixx="2.72836346546105E-06" ixy="7.0874539112887E-08" ixz="-2.27358946603912E-07" iyy="2.534724795085E-06" iyz="3.84763852522776E-07" izz="8.0196735325128E-07" />
            </inertial>
            <visual>
            <origin xyz="0 0 0" rpy="0 0 0" />
            <geometry>
                <mesh filename="package://teleop_leaders/description/meshes/trigger.stl" />
            </geometry>
            <material name="">
                <color rgba="0.792156862745098 0.819607843137255 0.933333333333333 1" />
            </material>
            </visual>
            <collision>
            <origin xyz="0 0 0" rpy="0 0 0" />
            <geometry>
                <mesh filename="package://teleop_leaders/description/meshes/trigger.stl" />
            </geometry>
            </collision>
        </link>
        <joint name="robot${id}/gripper" type="revolute">
            <origin xyz="0.0154268 0 0.0226837" rpy="0.0 0 0.000" />
            <parent link="robot${id}/handle" />
            <child link="robot${id}/trigger" />
            <axis xyz="0 -1 0" />
            <limit lower="0" upper="1.2" effort="1" velocity="3.15" />
        </joint>
        <xacro:SimpleTransmissionEffort n="gripper" joint="gripper" id="${id}" />
        <xacro:SimpleTransmissionPosition n="gripper" joint="gripper" id="${id}" />
        
    </xacro:macro>


    <xacro:macro name="papras_leader" params="id">
        <link name="robot${id}/base_link">
            <inertial>
                <origin xyz="-1.88052088812657E-05 -0.00215271082064172 0.0441443392060522" rpy="0 0 0" />
                <mass value="0.218376911489293" />
                <inertia ixx="0.000160297084827002" ixy="1.06759566549485E-08" ixz="-4.82637621739845E-08" iyy="0.000190111291063554" iyz="-5.70875681133123E-06" izz="9.3344618631843E-05"  />
            </inertial>
            <visual>
                <origin xyz="0 0 0" rpy="0 0 0" />
                <geometry>
                    <mesh filename="package://teleop_leaders/description/meshes/base_link.stl" />
                </geometry>
                <material name="">
                    <color rgba="0.752941176470588 0.752941176470588 0.752941176470588 1" />
                </material>
            </visual>
            <collision>
            <origin
                xyz="0 0 0" rpy="0 0 0" />
            <geometry>
                <mesh filename="package://teleop_leaders/description/meshes/base_link.stl" />
            </geometry>
            </collision>
        </link>
        <link name="robot${id}/link1">
            <inertial>
                <origin xyz="1.07552855510562E-15 -0.0191612202006195 0.000694792898736266" rpy="0 0 0" />
                <mass value="0.0174430259925429" />
                <inertia ixx="2.26902036919966E-06" ixy="2.45388006660206E-20" ixz="3.30361213696899E-19" iyy="1.37733605190437E-06" iyz="-1.48998380957681E-08" izz="1.99269200180191E-06" />
            </inertial>
            <visual>
                <origin xyz="0 0 0" rpy="0 0 0" />
                <geometry>
                    <mesh filename="package://teleop_leaders/description/meshes/papras/link1.stl" />
                </geometry>
                <material name="">
                    <color rgba="0.627450980392157 0.627450980392157 0.627450980392157 1" />
                </material>
            </visual>
            <collision>
                <origin xyz="0 0 0" rpy="0 0 0" />
                <geometry>
                    <mesh filename="package://teleop_leaders/description/meshes/papras/link1.stl" />
                </geometry>
            </collision>
        </link>
        <joint name="robot${id}/joint1" type="revolute">
            <origin xyz="-0.000125 0.0022 0.099" rpy="-1.5708 0 0" />
            <parent link="robot${id}/base_link" />
            <child link="robot${id}/link1" />
            <axis xyz="0 -1 0" />
            <limit lower="-${pi}" upper="${pi}" effort="1" velocity="3.15" />
        </joint>
        <xacro:SimpleTransmissionEffort n="1" joint="joint1" id="${id}" />
        <xacro:SimpleTransmissionPosition n="1" joint="joint1" id="${id}" />

        <link name="robot${id}/link2">
            <inertial>
                <origin xyz="0.000147982716840395 0.00451319547209069 -0.097270560393635" rpy="0 0 0" />
                <mass value="0.0814342847713924" />
                <inertia ixx="0.000131496864514129" ixy="1.51737391008811E-18" ixz="-1.48295342475051E-08" iyy="0.00013588019621793" iyz="1.45299795458879E-05" izz="2.43781225621918E-05" />
            </inertial>
            <visual>
                <origin xyz="0 0 0" rpy="0 0 0" />
                <geometry>
                    <mesh filename="package://teleop_leaders/description/meshes/papras/link2.stl" />
                </geometry>
                <material
                    name="">
                    <color
                    rgba="0.792156862745098 0.819607843137255 0.933333333333333 1" />
                </material>
            </visual>
            <collision>
            <origin
                xyz="0 0 0"
                rpy="0 0 0" />
            <geometry>
                <mesh filename="package://teleop_leaders/description/meshes/papras/link2.stl" />
            </geometry>
            </collision>
        </link>
        <joint name="robot${id}/joint2" type="revolute">
            <origin xyz="0 -0.029 0" rpy="1.5708 1.5708 ${pi}" />
            <parent link="robot${id}/link1" />
            <child link="robot${id}/link2" />
            <axis xyz="1 0 0" />
            <limit lower="-${pi}" upper="${pi}" effort="1" velocity="3.15" />
        </joint>
        <xacro:SimpleTransmissionEffort n="2" joint="joint2" id="${id}" />
        <xacro:SimpleTransmissionPosition n="2" joint="joint2" id="${id}" />

        <link name="robot${id}/link3">
            <inertial>
            <origin xyz="-0.0180594814950693 -1.63627658705211E-08 -0.0722877425230301" rpy="0 0 0" />
            <mass value="0.0654267493288997" />
            <inertia ixx="7.49414046149126E-05" ixy="3.98289349653685E-11" ixz="3.50441605989892E-06" iyy="7.99497837595888E-05" iyz="-5.50559303414792E-11" izz="1.63780078786181E-05" />
            </inertial>
            <visual>
            <origin xyz="0 0 0" rpy="0 0 0" />
            <geometry>
                <mesh filename="package://teleop_leaders/description/meshes/papras/link3.stl" />
            </geometry>
            <material name="">
                <color rgba="0.792156862745098 0.819607843137255 0.933333333333333 1" />
            </material>
            </visual>
            <collision>
            <origin xyz="0 0 0" rpy="0 0 0" />
            <geometry>
                <mesh filename="package://teleop_leaders/description/meshes/papras/link3.stl" />
            </geometry>
            </collision>
        </link>
        <joint name="robot${id}/joint3" type="revolute">
            <origin xyz="0 0.0195 -0.1716" rpy="0 -1.5708 1.5708" />
            <parent link="robot${id}/link2" />
            <child link="robot${id}/link3" />
            <axis xyz="0 -1 0" />
            <limit lower="-${pi}" upper="${pi}" effort="1" velocity="3.15" />
        </joint>
        <xacro:SimpleTransmissionEffort n="3" joint="joint3" id="${id}" />
        <xacro:SimpleTransmissionPosition n="3" joint="joint3" id="${id}" />

        <link name="robot${id}/link4">
            <inertial>
            <origin xyz="0.000447858160341448 -0.00117107937366287 -0.0280375991206876" rpy="0 0 0" />
            <mass value="0.0269077999710614" />
            <inertia ixx="3.93965337255511E-06" ixy="2.33053708688373E-15" ixz="-1.48295276394878E-08" iyy="4.44540833990355E-06" iyz="-1.58545336317713E-07" izz="3.49024355481955E-06" />
            </inertial>
            <visual>
            <origin xyz="0 0 0" rpy="0 0 0" />
            <geometry>
                <mesh filename="package://teleop_leaders/description/meshes/papras/link4.stl" />
            </geometry>
            <material name="">
                <color rgba="0.792156862745098 0.819607843137255 0.933333333333333 1" />
            </material>
            </visual>
            <collision>
            <origin xyz="0 0 0" rpy="0 0 0" />
            <geometry>
                <mesh filename="package://teleop_leaders/description/meshes/papras/link4.stl" />
            </geometry>
            </collision>
        </link>
        <joint name="robot${id}/joint4" type="revolute">
            <origin xyz="-0.0194 0 -0.12304" rpy="0 0 -1.5708" />
            <parent link="robot${id}/link3" />
            <child link="robot${id}/link4" />
            <axis xyz="0 0 -1" />
            <limit lower="-${pi}" upper="${pi}" effort="1" velocity="3.15" />
        </joint>
        <xacro:SimpleTransmissionEffort n="4" joint="joint4" id="${id}" />
        <xacro:SimpleTransmissionPosition n="4" joint="joint4" id="${id}" />

        <link name="robot${id}/link5">
            <inertial>
            <origin xyz="-1.93174924667527E-09 0.0359667259162841 -0.00685952331822111" rpy="0 0 0" />
            <mass value="0.0354352330271564" />
            <inertia ixx="1.046584774501E-05" ixy="-8.1705364395442E-13" ixz="-2.6487940954783E-11" iyy="8.94432356070269E-06" iyz="3.1177092144739E-09" izz="4.68872581327118E-06" />
            </inertial>
            <visual>
            <origin xyz="0 0 0" rpy="0 0 0" />
            <geometry>
                <mesh filename="package://teleop_leaders/description/meshes/papras/link5.stl" />
            </geometry>
            <material name="">
                <color rgba="0.627450980392157 0.627450980392157 0.627450980392157 1" />
            </material>
            </visual>
            <collision>
            <origin xyz="0 0 0" rpy="0 0 0" />
            <geometry>
                <mesh filename="package://teleop_leaders/description/meshes/papras/link5.stl" />
            </geometry>
            </collision>
        </link>
        <joint name="robot${id}/joint5" type="revolute">
            <origin xyz="0 0 -0.0475" rpy="-1.5708 0 -1.5708" />
            <parent link="robot${id}/link4" />
            <child link="robot${id}/link5" />
            <axis xyz="0 0 1" />
            <limit lower="-${pi}" upper="${pi}" effort="1" velocity="3.15" />
        </joint>
        <xacro:SimpleTransmissionEffort n="5" joint="joint5" id="${id}" />
        <xacro:SimpleTransmissionPosition n="5" joint="joint5" id="${id}" />

        <link name="robot${id}/handle">
            <inertial>
            <origin xyz="-0.0269504648321372 -0.000444552753820911 0.00944823169908937" rpy="0 0 0" />
            <mass value="0.0792318961261061" />
            <inertia ixx="3.30813970525119E-05" ixy="1.1856468521745E-05" ixz="8.98678207145682E-07" iyy="3.49786415297126E-05" iyz="-5.09722128514016E-07" izz="5.60466661401102E-05" />
            </inertial>
            <visual>
            <origin xyz="0 0 0" rpy="0 0 0" />
            <geometry>
                <mesh filename="package://teleop_leaders/description/meshes/handle.stl" />
            </geometry>
            <material name="">
                <color rgba="0.792156862745098 0.819607843137255 0.933333333333333 1" />
            </material>
            </visual>
            <collision>
            <origin xyz="0.01 0 0" rpy="0 0 0" />
            <geometry>
                <mesh filename="package://teleop_leaders/description/meshes/handle.stl" />
            </geometry>
            </collision>
        </link>
        <joint name="robot${id}/joint6" type="revolute">
            <origin xyz="0.000 0.053 0.0" rpy="-1.0233 1.4705 0.54972" />
            <parent link="robot${id}/link5" />
            <child link="robot${id}/handle" />
            <axis xyz="0.052336 0 0.99863" />
            <limit lower="-${pi}" upper="${pi}" effort="1" velocity="3.15" />
        </joint>
        <xacro:SimpleTransmissionEffort n="6" joint="joint6" id="${id}" />
        <xacro:SimpleTransmissionPosition n="6" joint="joint6" id="${id}" />

        <link name="robot${id}/trigger">
            <inertial>
            <origin xyz="0.0050484710643748 0.00657608716575382 0.0232192535585892" rpy="0 0 0" />
            <mass value="0.0113373798119285" />
            <inertia ixx="2.72836346546105E-06" ixy="7.0874539112887E-08" ixz="-2.27358946603912E-07" iyy="2.534724795085E-06" iyz="3.84763852522776E-07" izz="8.0196735325128E-07" />
            </inertial>
            <visual>
            <origin xyz="0 0 0" rpy="0 0 0" />
            <geometry>
                <mesh filename="package://teleop_leaders/description/meshes/trigger.stl" />
            </geometry>
            <material name="">
                <color rgba="0.792156862745098 0.819607843137255 0.933333333333333 1" />
            </material>
            </visual>
            <collision>
            <origin xyz="0 0 0" rpy="0 0 0" />
            <geometry>
                <mesh filename="package://teleop_leaders/description/meshes/trigger.stl" />
            </geometry>
            </collision>
        </link>
        <joint name="robot${id}/gripper" type="revolute">
            <origin xyz="0.0154268 0 0.0226837" rpy="0.0 0 0.000" />
            <parent link="robot${id}/handle" />
            <child link="robot${id}/trigger" />
            <axis xyz="0 -1 0" />
            <limit lower="0" upper="1.2" effort="1" velocity="3.15" />
        </joint>
        <xacro:SimpleTransmissionEffort n="gripper" joint="gripper" id="${id}" />
        <xacro:SimpleTransmissionPosition n="gripper" joint="gripper" id="${id}" />

    </xacro:macro>


    <xacro:macro name="papras7dof_leader" params="id">
        <link name="robot${id}/base_link">
            <inertial>
                <origin xyz="-1.88052088812657E-05 -0.00215271082064172 0.0441443392060522" rpy="0 0 0" />
                <mass value="0.218376911489293" />
                <inertia ixx="0.000160297084827002" ixy="1.06759566549485E-08" ixz="-4.82637621739845E-08" iyy="0.000190111291063554" iyz="-5.70875681133123E-06" izz="9.3344618631843E-05"  />
            </inertial>
            <visual>
                <origin xyz="0 0 0" rpy="0 0 0" />
                <geometry>
                    <mesh filename="package://teleop_leaders/description/meshes/base_link.stl" />
                </geometry>
                <material name="">
                    <color rgba="0.752941176470588 0.752941176470588 0.752941176470588 1" />
                </material>
            </visual>
            <collision>
            <origin
                xyz="0 0 0" rpy="0 0 0" />
            <geometry>
                <mesh filename="package://teleop_leaders/description/meshes/base_link.stl" />
            </geometry>
            </collision>
        </link>
        <link name="robot${id}/link1">
            <inertial>
                <origin xyz="8.03381307583049E-16 0.0183891548632449 -0.00065273513210628" rpy="0 0 0" />
                <mass value="0.0184621083060345" />
                <inertia ixx="2.40713355161292E-06" ixy="-2.72793224052933E-21" ixz="1.89321316204573E-15" iyy="1.52798370468232E-06" iyz="-1.482953424559E-08" izz="2.03767449056785E-06" />
            </inertial>
            <visual>
                <origin xyz="0 0 0" rpy="0 0 0" />
                <geometry>
                    <mesh filename="package://teleop_leaders/description/meshes/papras_7dof/link1.stl" />
                </geometry>
                <material name="">
                    <color rgba="0.627450980392157 0.627450980392157 0.627450980392157 1" />
                </material>
            </visual>
            <collision>
                <origin xyz="0 0 0" rpy="0 0 0" />
                <geometry>
                    <mesh filename="package://teleop_leaders/description/meshes/papras_7dof/link1.stl" />
                </geometry>
            </collision>
        </link>
        <joint name="robot${id}/joint1" type="revolute">
            <origin xyz="-0.000125 0.0022 0.099" rpy="1.5708 0 0" />
            <parent link="robot${id}/base_link" />
            <child link="robot${id}/link1" />
            <axis xyz="0 1 0" />
            <limit lower="-${pi}" upper="${pi}" effort="1" velocity="3.15" />
        </joint>
        <xacro:SimpleTransmissionEffort n="1" joint="joint1" id="${id}" />
        <xacro:SimpleTransmissionPosition n="1" joint="joint1" id="${id}" />

        <link name="robot${id}/link2">
            <inertial>
                <origin xyz="0.000147982716840395 0.00451319547209069 -0.097270560393635" rpy="0 0 0" />
                <mass value="0.0814342847713924" />
                <inertia ixx="0.000131496864514129" ixy="1.51737391008811E-18" ixz="-1.48295342475051E-08" iyy="0.00013588019621793" iyz="1.45299795458879E-05" izz="2.43781225621918E-05" />
            </inertial>
            <visual>
                <origin xyz="0 0 0" rpy="0 0 0" />
                <geometry>
                    <mesh filename="package://teleop_leaders/description/meshes/papras_7dof/link2.stl" />
                </geometry>
                <material
                    name="">
                    <color
                    rgba="0.792156862745098 0.819607843137255 0.933333333333333 1" />
                </material>
            </visual>
            <collision>
            <origin
                xyz="0 0 0"
                rpy="0 0 0" />
            <geometry>
                <mesh filename="package://teleop_leaders/description/meshes/papras_7dof/link2.stl" />
            </geometry>
            </collision>
        </link>
        <joint name="robot${id}/joint2" type="revolute">
            <origin  xyz="0 0.029 0" rpy="3.1416 0 3.1416"  />
            <parent link="robot${id}/link1" />
            <child link="robot${id}/link2" />
            <axis xyz="0 0 -1" />
            <limit lower="-${pi}" upper="${pi}" effort="1" velocity="3.15" />
        </joint>
        <xacro:SimpleTransmissionEffort n="2" joint="joint2" id="${id}" />
        <xacro:SimpleTransmissionPosition n="2" joint="joint2" id="${id}" />

        <link name="robot${id}/link3">
            <inertial>
            <origin xyz="-0.0180594814950693 -1.63627658705211E-08 -0.0722877425230301" rpy="0 0 0" />
            <mass value="0.0654267493288997" />
            <inertia ixx="7.49414046149126E-05" ixy="3.98289349653685E-11" ixz="3.50441605989892E-06" iyy="7.99497837595888E-05" iyz="-5.50559303414792E-11" izz="1.63780078786181E-05" />
            </inertial>
            <visual>
            <origin xyz="0 0 0" rpy="0 0 0" />
            <geometry>
                <mesh filename="package://teleop_leaders/description/meshes/papras_7dof/link3.stl" />
            </geometry>
            <material name="">
                <color rgba="0.792156862745098 0.819607843137255 0.933333333333333 1" />
            </material>
            </visual>
            <collision>
            <origin xyz="0 0 0" rpy="0 0 0" />
            <geometry>
                <mesh filename="package://teleop_leaders/description/meshes/papras_7dof/link3.stl" />
            </geometry>
            </collision>
        </link>
        <joint name="robot${id}/joint3" type="revolute">
            <origin xyz="-0.0001 0.10079 0" rpy="1.5708 1.5708 0" />
            <parent link="robot${id}/link2" />
            <child link="robot${id}/link3" />
            <axis xyz="0 0 -1" />
            <limit lower="-${pi}" upper="${pi}" effort="1" velocity="3.15" />
        </joint>
        <xacro:SimpleTransmissionEffort n="3" joint="joint3" id="${id}" />
        <xacro:SimpleTransmissionPosition n="3" joint="joint3" id="${id}" />

        <link name="robot${id}/link4">
            <inertial>
            <origin xyz="0.000447858160341448 -0.00117107937366287 -0.0280375991206876" rpy="0 0 0" />
            <mass value="0.0269077999710614" />
            <inertia ixx="3.93965337255511E-06" ixy="2.33053708688373E-15" ixz="-1.48295276394878E-08" iyy="4.44540833990355E-06" iyz="-1.58545336317713E-07" izz="3.49024355481955E-06" />
            </inertial>
            <visual>
            <origin xyz="0 0 0" rpy="0 0 0" />
            <geometry>
                <mesh filename="package://teleop_leaders/description/meshes/papras_7dof/link4.stl" />
            </geometry>
            <material name="">
                <color rgba="0.792156862745098 0.819607843137255 0.933333333333333 1" />
            </material>
            </visual>
            <collision>
            <origin xyz="0 0 0" rpy="0 0 0" />
            <geometry>
                <mesh filename="package://teleop_leaders/description/meshes/papras_7dof/link4.stl" />
            </geometry>
            </collision>
        </link>
        <joint name="robot${id}/joint4" type="revolute">
            <origin  xyz="0 0.01952 -0.070988" rpy="1.5708 -1.5708 0" />
            <parent link="robot${id}/link3" />
            <child link="robot${id}/link4" />
            <axis xyz="0 -1 0" />
            <limit lower="-${pi}" upper="${pi}" effort="1" velocity="3.15" />
        </joint>
        <xacro:SimpleTransmissionEffort n="4" joint="joint4" id="${id}" />
        <xacro:SimpleTransmissionPosition n="4" joint="joint4" id="${id}" />

        <link name="robot${id}/link5">
            <inertial>
            <origin xyz="-1.93174924667527E-09 0.0359667259162841 -0.00685952331822111" rpy="0 0 0" />
            <mass value="0.0354352330271564" />
            <inertia ixx="1.046584774501E-05" ixy="-8.1705364395442E-13" ixz="-2.6487940954783E-11" iyy="8.94432356070269E-06" iyz="3.1177092144739E-09" izz="4.68872581327118E-06" />
            </inertial>
            <visual>
            <origin xyz="0 0 0" rpy="0 0 0" />
            <geometry>
                <mesh filename="package://teleop_leaders/description/meshes/papras_7dof/link5.stl" />
            </geometry>
            <material name="">
                <color rgba="0.627450980392157 0.627450980392157 0.627450980392157 1" />
            </material>
            </visual>
            <collision>
            <origin xyz="0 0 0" rpy="0 0 0" />
            <geometry>
                <mesh filename="package://teleop_leaders/description/meshes/papras_7dof/link5.stl" />
            </geometry>
            </collision>
        </link>
        <joint name="robot${id}/joint5" type="revolute">
            <origin xyz="-0.01952 0 -0.12037" rpy="0 0 -1.5708" />
            <parent link="robot${id}/link4" />
            <child link="robot${id}/link5" />
            <axis xyz="0 0 -1" />
            <limit lower="-${pi}" upper="${pi}" effort="1" velocity="3.15" />
        </joint>
        <xacro:SimpleTransmissionEffort n="5" joint="joint5" id="${id}" />
        <xacro:SimpleTransmissionPosition n="5" joint="joint5" id="${id}" />

        <link name="robot${id}/link6">
            <inertial>
            <origin xyz="-1.2083725686729E-08 -0.00604745156102854 -0.0534802275374367" rpy="0 0 0" />
            <mass value="0.0465686690697251" />
            <inertia ixx="1.046584774501E-05" ixy="-8.1705364395442E-13" ixz="-2.6487940954783E-11" iyy="8.94432356070269E-06" iyz="3.1177092144739E-09" izz="4.68872581327118E-06" />
            </inertial>
            <visual>
            <origin xyz="0 0 0" rpy="0 0 0" />
            <geometry>
                <mesh filename="package://teleop_leaders/description/meshes/papras_7dof/link6.stl" />
            </geometry>
            <material name="">
                <color rgba="0.627450980392157 0.627450980392157 0.627450980392157 1" />
            </material>
            </visual>
            <collision>
            <origin xyz="0 0 0" rpy="0 0 0" />
            <geometry>
                <mesh filename="package://teleop_leaders/description/meshes/papras_7dof/link6.stl" />
            </geometry>
            </collision>
        </link>
        <joint name="robot${id}/joint6" type="revolute">
            <origin xyz="0 0 -0.0475000000000001" rpy="0 0 1.5708" />
            <parent link="robot${id}/link5" />
            <child link="robot${id}/link6" />
            <axis xyz="0 -1 0" />
            <limit lower="-${pi}" upper="${pi}" effort="1" velocity="3.15" />
        </joint>
        <xacro:SimpleTransmissionEffort n="6" joint="joint6" id="${id}" />
        <xacro:SimpleTransmissionPosition n="6" joint="joint6" id="${id}" />

        <link name="robot${id}/handle">
            <inertial>
            <origin xyz="-0.0269504648321372 -0.000444552753820911 0.00944823169908937" rpy="0 0 0" />
            <mass value="0.0792318961261061" />
            <inertia ixx="3.30813970525119E-05" ixy="1.1856468521745E-05" ixz="8.98678207145682E-07" iyy="3.49786415297126E-05" iyz="-5.09722128514016E-07" izz="5.60466661401102E-05" />
            </inertial>
            <visual>
            <origin xyz="0 0 0" rpy="0 0 0" />
            <geometry>
                <mesh filename="package://teleop_leaders/description/meshes/handle.stl" />
            </geometry>
            <material name="">
                <color rgba="0.792156862745098 0.819607843137255 0.933333333333333 1" />
            </material>
            </visual>
            <collision>
            <origin xyz="0.01 0 0" rpy="0 0 0" />
            <geometry>
                <mesh filename="package://teleop_leaders/description/meshes/handle.stl" />
            </geometry>
            </collision>
        </link>
        <joint name="robot${id}/joint7" type="revolute">
            <origin xyz="0 1E-05 -0.076464" rpy="${pi} 0.05236 1.576" />
            <parent link="robot${id}/link6" />
            <child link="robot${id}/handle" />
            <axis xyz="0.052336 0 0.99863" />
            <limit lower="-${pi}" upper="${pi}" effort="1" velocity="3.15" />
        </joint>
        <xacro:SimpleTransmissionEffort n="7" joint="joint7" id="${id}" />
        <xacro:SimpleTransmissionPosition n="7" joint="joint7" id="${id}" />

        <link name="robot${id}/trigger">
            <inertial>
            <origin xyz="0.0050484710643748 0.00657608716575382 0.0232192535585892" rpy="0 0 0" />
            <mass value="0.0113373798119285" />
            <inertia ixx="2.72836346546105E-06" ixy="7.0874539112887E-08" ixz="-2.27358946603912E-07" iyy="2.534724795085E-06" iyz="3.84763852522776E-07" izz="8.0196735325128E-07" />
            </inertial>
            <visual>
            <origin xyz="0 0 0" rpy="0 0 0" />
            <geometry>
                <mesh filename="package://teleop_leaders/description/meshes/trigger.stl" />
            </geometry>
            <material name="">
                <color rgba="0.792156862745098 0.819607843137255 0.933333333333333 1" />
            </material>
            </visual>
            <collision>
            <origin xyz="0 0 0" rpy="0 0 0" />
            <geometry>
                <mesh filename="package://teleop_leaders/description/meshes/trigger.stl" />
            </geometry>
            </collision>
        </link>
        <joint name="robot${id}/gripper" type="revolute">
            <origin xyz="0.0154268 0 0.0226837" rpy="0.0 0 0.000" />
            <parent link="robot${id}/handle" />
            <child link="robot${id}/trigger" />
            <axis xyz="0 -1 0" />
            <limit lower="0" upper="1.2" effort="1" velocity="3.15" />
        </joint> 
        <xacro:SimpleTransmissionEffort n="gripper" joint="gripper" id="${id}" />
        <xacro:SimpleTransmissionPosition n="gripper" joint="gripper" id="${id}" />
        
    </xacro:macro>

</robot>
