<?xml version="1.0"?>
<robot xmlns:xacro="http://www.ros.org/wiki/xacro">
     <xacro:macro name="spot" params="tf_prefix">

        <link name="${tf_prefix}body">
            <visual>
                <geometry>
                    <mesh filename="package://spot_description/meshes/body.dae" />
                </geometry>
            </visual>
            <collision>
                <geometry>
                    <mesh
                        filename="package://spot_description/meshes/body_collision.stl" />
                </geometry>
            </collision>
            <inertial>
                <mass value="16.0"/>
                <inertia ixx="0.0973333333333" ixy="0.0" ixz="0.0" iyy="1.02466666667" iyz="0.0" izz="1.04493333333"/>
            </inertial>
             <!-- <inertial>
                <origin rpy="0.0 0.0 0.0"
                    xyz="0.006394396536052227 -9.812158532440662e-05 0.0009113792330026627" />
                <mass value="80.86" />
                <inertia ixx="0.49189833333" ixy="0.0" ixz="0.0" iyy="5.178409"
                    iyz="0.0" izz="5.28083183333" />
            </inertial> -->
        </link>

        <link name="${tf_prefix}base_link">
        </link>
        <joint name="${tf_prefix}base_link_joint" type="fixed">
            <origin xyz="0 0 0" rpy="0 0 0" />
            <parent link="${tf_prefix}body" />
            <child link="${tf_prefix}base_link" />
        </joint>

        <link name="${tf_prefix}front_rail">
            <!-- <inertial>
                <origin rpy="0. 0. 0." xyz="0. 0. 0." />
                <mass value="1.0e-6" />
                <inertia ixx="1.0e-9" ixy="0.0" ixz="0.0" iyy="1.0e-9" iyz="0.0" izz="1.0e-9" />
            </inertial> -->
        </link>
        <joint name="${tf_prefix}front_rail_joint" type="fixed">
            <origin xyz="0.223 0 0.0805" rpy="0 0 0" />
            <parent link="${tf_prefix}body" />
            <child link="${tf_prefix}front_rail" />
        </joint>

        <link name="${tf_prefix}rear_rail">
            <!-- <inertial>
                <origin rpy="0. 0. 0." xyz="0. 0. 0." />
                <mass value="1.0e-6" />
                <inertia ixx="1.0e-9" ixy="0.0" ixz="0.0" iyy="1.0e-9" iyz="0.0" izz="1.0e-9" />
            </inertial> -->
        </link>
        <joint name="${tf_prefix}rear_rail_joint" type="fixed">
            <origin xyz="-0.223 0 0.0805" rpy="0 0 0" />
            <parent link="${tf_prefix}body" />
            <child link="${tf_prefix}rear_rail" />
        </joint>

        <link name="${tf_prefix}front_left_hip">
            <visual>
                <geometry>
                    <mesh
                        filename="package://spot_description/meshes/front_left_hip.dae" />
                </geometry>
            </visual>
            <collision>
                <geometry>
                    <mesh filename="package://spot_description/meshes/front_left_hip_collision.stl" />
                </geometry>
            </collision>
            <inertial>
                <origin rpy="-0.716521349312305 0.02956473059648479 0.03655230014702582"
                    xyz="-0.005374345928430557 0.012841847725212574 9.875232353806496e-05" />
                <mass value="1.68" />
                <inertia ixx="0.0021147398873455382" ixy="0.0" ixz="0.0" iyy="0.0018129577956607131"
                    iyz="0.0" izz="0.002265435737304666" />
            </inertial>
        </link>
        <joint name="${tf_prefix}front_left_hip_x" type="revolute">
            <origin xyz="0.29785 0.05500 0.00000" rpy="0 0 0" />
            <axis xyz="1 0 0" />
            <parent link="${tf_prefix}body" />
            <child link="${tf_prefix}front_left_hip" />
            <limit effort="1000" velocity="1000.00" lower="-0.78539816339744827899"
                upper="0.78539816339744827899" />
            <!-- <dynamics damping="7.0" friction="3.0" /> -->
        </joint>
        <gazebo reference="${tf_prefix}front_left_hip_x">
            <!-- <kp>10000000.0</kp>
            <kd>50.0</kd> -->
        </gazebo>
        <transmission name="front_left_hip_x_trans">
        <type>transmission_interface/SimpleTransmission</type>
            <joint name="front_left_hip_x">
                    <hardwareInterface>hardware_interface/EffortJointInterface</hardwareInterface>
                </joint>
            <actuator name="front_left_hip_x">
                    <mechanicalReduction>1</mechanicalReduction>
                    <hardwareInterface>hardware_interface/EffortJointInterface</hardwareInterface>
            </actuator>
        </transmission>
        <link name="${tf_prefix}front_left_upper_leg">
            <visual>
                <geometry>
                    <mesh
                        filename="package://spot_description/meshes/front_left_upper_leg.dae" />
                </geometry>
            </visual>
            <collision>
                <geometry>
                    <mesh
                        filename="package://spot_description/meshes/front_left_upper_leg_collision.stl" />
                </geometry>
            </collision>
            <inertial>
                <origin rpy="-0.26437828203369795 -0.04853174570753804 0.024046963096353124"
                    xyz="0.005142373498529196 -0.0024323679972440004 -0.12100915610790253" />
                <mass value="2.34" />
                <inertia ixx="0.02755964961185679" ixy="0.0" ixz="0.0" iyy="0.027354914287651046"
                    iyz="0.0" izz="0.002848145546743553" />
            </inertial>
        </link>
        <joint name="${tf_prefix}front_left_hip_y" type="revolute">
            <origin xyz="0.0 0.110945 0.0" rpy="0 0 0" />
            <axis xyz="0 1 0" />
            <parent link="${tf_prefix}front_left_hip" />
            <child link="${tf_prefix}front_left_upper_leg" />
            <limit effort="1000" velocity="1000.00" lower="-0.89884456477707963539"
                upper="2.2951079663725435509" />
            <!--<dynamics damping="7.0" friction="3.0" /> -->

        </joint>
        <gazebo reference="${tf_prefix}front_left_hip_y">
            <!-- <kp>10000000.0</kp>
            <kd>50.0</kd> -->
        </gazebo>
        <transmission name="front_left_hip_y_trans">
            <type>transmission_interface/SimpleTransmission</type>
            <joint name="front_left_hip_y">
                    <hardwareInterface>hardware_interface/EffortJointInterface</hardwareInterface>
                </joint>
            <actuator name="front_left_hip_y">
                    <mechanicalReduction>1</mechanicalReduction>
                    <hardwareInterface>hardware_interface/EffortJointInterface</hardwareInterface>
            </actuator>
        </transmission>
        <link name="${tf_prefix}front_left_lower_leg">
            <visual>
                <geometry>
                    <mesh
                        filename="package://spot_description/meshes/front_left_lower_leg.dae" />
                </geometry>
            </visual>
            <collision>
                <geometry>
                    <mesh
                        filename="package://spot_description/meshes/front_left_lower_leg_collision.stl" />
                </geometry>
            </collision>
            <collision>
                <origin xyz="0.0 0.0 -0.3365" rpy="0 0 0" />
                <geometry>
                    <sphere radius="0.036"/>
                </geometry>
            </collision>
            <inertial>
                <origin rpy="-0.007266925694167092 -0.009591807116834161 0.00035255970529224356"
                    xyz="0.00225794012658298 4.607596201822162e-05 -0.1800822913646698" />
                <mass value="0.35" />
                <inertia ixx="0.003999022654901177" ixy="0.0" ixz="0.0" iyy="0.0040503157598010785"
                    iyz="0.0" izz="0.0001493402097647426" />
            </inertial>
        </link>
        <joint name="${tf_prefix}front_left_knee" type="revolute">
            <origin xyz="0.025 0.000 -0.3205" rpy="0 0 0" />
            <axis xyz="0 1 0" />
            <parent link="${tf_prefix}front_left_upper_leg" />
            <child link="${tf_prefix}front_left_lower_leg" />
            <limit effort="1000" velocity="1000.00" lower="-2.7929" upper="-0.254801" />
            <!--<dynamics damping="7.0" friction="3.0" /> -->

        </joint>
        <gazebo reference="${tf_prefix}front_left_knee">
            <!-- <kp>10000000.0</kp>
            <kd>50.0</kd> -->
        </gazebo>
        <link name="${tf_prefix}front_left_ee"/>
        <joint name="${tf_prefix}front_left_ee" type="fixed">
            <origin xyz="0.000 0.000 -0.37" rpy="0 0 0" />
            <parent link="${tf_prefix}front_left_lower_leg" />
            <child link="${tf_prefix}front_left_ee" />
        </joint>
        <transmission name="front_left_knee_trans">
            <type>transmission_interface/SimpleTransmission</type>
            <joint name="front_left_knee">
                    <hardwareInterface>hardware_interface/EffortJointInterface</hardwareInterface>
                </joint>
            <actuator name="front_left_knee">
                    <mechanicalReduction>1</mechanicalReduction>
                    <hardwareInterface>hardware_interface/EffortJointInterface</hardwareInterface>
            </actuator>
        </transmission>
        <link name="${tf_prefix}front_right_hip">
            <visual>
                <geometry>
                    <mesh
                        filename="package://spot_description/meshes/front_right_hip.dae" />
                </geometry>
            </visual>
            <collision>
                <geometry>
                    <mesh filename="package://spot_description/meshes/front_right_hip_collision.stl" />
                </geometry>
            </collision>
            <inertial>
                <origin rpy="0.7165213493123055 -0.02956473059648479 0.03655230014702582"
                    xyz="-0.005374345928430557 -0.012841847725212574 -9.875232353806496e-05" />
                <mass value="1.68" />
                <inertia ixx="0.0021147398873455382" ixy="0.0" ixz="0.0" iyy="0.0018129577956607131"
                    iyz="0.0" izz="0.002265435737304666" />
            </inertial>
        </link>
        <joint name="${tf_prefix}front_right_hip_x" type="revolute">
            <origin xyz="0.29785 -0.05500 0.00000" rpy="0 0 0" />
            <axis xyz="1 0 0" />
            <parent link="${tf_prefix}body" />
            <child link="${tf_prefix}front_right_hip" />
            <limit effort="1000" velocity="1000.00" lower="-0.78539816339744827899"
                upper="0.78539816339744827899" />
            <!--<dynamics damping="7.0" friction="3.0" /> -->
 
        </joint>
        <gazebo reference="${tf_prefix}front_right_hip_x">
            <!-- <kp>10000000.0</kp>
            <kd>50.0</kd> -->
        </gazebo>
        <transmission name="front_right_hip_x_trans">
            <type>transmission_interface/SimpleTransmission</type>
            <joint name="front_right_hip_x">
                    <hardwareInterface>hardware_interface/EffortJointInterface</hardwareInterface>
                </joint>
            <actuator name="front_right_hip_x">
                    <mechanicalReduction>1</mechanicalReduction>
                    <hardwareInterface>hardware_interface/EffortJointInterface</hardwareInterface>
            </actuator>
        </transmission>
        <link name="${tf_prefix}front_right_upper_leg">
            <visual>
                <geometry>
                    <mesh
                        filename="package://spot_description/meshes/front_right_upper_leg.dae" />
                </geometry>
            </visual>
            <collision>
                <geometry>
                    <mesh
                        filename="package://spot_description/meshes/front_right_upper_leg_collision.stl" />
                </geometry>
            </collision>
            <inertial>
                <origin rpy="0.2643905306958363 -0.04853174688302708 -0.024046943559834943"
                    xyz="0.005142373498529196 0.0024323677644133568 -0.12100915610790253" />
                <mass value="2.34" />
                <inertia ixx="0.02755964678927691" ixy="0.0" ixz="0.0" iyy="0.02735491706466737"
                    iyz="0.0" izz="0.0028481453594764797" />
            </inertial>
        </link>
        <joint name="${tf_prefix}front_right_hip_y" type="revolute">
            <origin xyz="0.0 -0.110945 0.0" rpy="0 0 0" />
            <axis xyz="0 1 0" />
            <parent link="${tf_prefix}front_right_hip" />
            <child link="${tf_prefix}front_right_upper_leg" />
            <limit effort="1000" velocity="1000.00" lower="-0.89884456477707963539"
                upper="2.2951079663725435509" />
            <!--<dynamics damping="7.0" friction="3.0" /> -->
   
        </joint>
        <link name="${tf_prefix}front_right_ee"/>
        <joint name="${tf_prefix}front_right_ee" type="fixed">
            <origin xyz="0.000 0.000 -0.37" rpy="0 0 0" />
            <parent link="${tf_prefix}front_right_lower_leg" />
            <child link="${tf_prefix}front_right_ee" />
        </joint>
        <gazebo reference="${tf_prefix}front_right_hip_y">
            <!-- <kp>10000000.0</kp>
            <kd>50.0</kd> -->
        </gazebo>
        <transmission name="front_right_hip_y_trans">
            <type>transmission_interface/SimpleTransmission</type>
            <joint name="front_right_hip_y">
                    <hardwareInterface>hardware_interface/EffortJointInterface</hardwareInterface>
                </joint>
            <actuator name="front_right_hip_y">
                    <mechanicalReduction>1</mechanicalReduction>
                    <hardwareInterface>hardware_interface/EffortJointInterface</hardwareInterface>
            </actuator>
        </transmission>
        <link name="${tf_prefix}front_right_lower_leg">
            <visual>
                <geometry>
                    <mesh
                        filename="package://spot_description/meshes/front_right_lower_leg.dae" />
                </geometry>
            </visual>
            <collision>
                <geometry>
                    <mesh
                        filename="package://spot_description/meshes/front_right_lower_leg_collision.stl" />
                </geometry>
            </collision>
            <collision>
                <origin xyz="0.0 0.0 -0.3365" rpy="0 0 0" />
                <geometry>
                    <sphere radius="0.036"/>
                </geometry>
            </collision>
            <inertial>
                <origin rpy="-0.007266925694167092 -0.009591807116834161 0.00035255970529224356"
                    xyz="0.00225794012658298 4.607596201822162e-05 -0.1800822913646698" />
                <mass value="0.35" />
                <inertia ixx="0.003999022654901177" ixy="0.0" ixz="0.0" iyy="0.0040503157598010785"
                    iyz="0.0" izz="0.0001493402097647426" />
            </inertial>
        </link>
        <joint name="${tf_prefix}front_right_knee" type="revolute">
            <origin xyz="0.025 0.000 -0.3205" rpy="0 0 0" />
            <axis xyz="0 1 0" />
            <parent link="${tf_prefix}front_right_upper_leg" />
            <child link="${tf_prefix}front_right_lower_leg" />
            <limit effort="1000" velocity="1000.00" lower="-2.7929" upper="-0.247563" />
            <!--<dynamics damping="7.0" friction="3.0" /> -->
    
        </joint>
        <gazebo reference="${tf_prefix}front_right_knee">
            <!-- <kp>10000000.0</kp>
            <kd>50.0</kd> -->
        </gazebo>
        <transmission name="front_right_knee_trans">
            <type>transmission_interface/SimpleTransmission</type>
            <joint name="front_right_knee">
                    <hardwareInterface>hardware_interface/EffortJointInterface</hardwareInterface>
                </joint>
            <actuator name="front_right_knee">
                    <mechanicalReduction>1</mechanicalReduction>
                    <hardwareInterface>hardware_interface/EffortJointInterface</hardwareInterface>
            </actuator>
        </transmission>
        <link name="${tf_prefix}rear_left_hip">
            <visual>
                <geometry>
                    <mesh
                        filename="package://spot_description/meshes/rear_left_hip.dae" />
                </geometry>
            </visual>
            <collision>
                <geometry>
                    <mesh filename="package://spot_description/meshes/rear_left_hip_collision.stl" />
                </geometry>
            </collision>
            <inertial>
                <origin rpy="0.7165213493123055 -0.02956473059648479 0.03655230014702582"
                    xyz="-0.005374345928430557 -0.012841847725212574 -9.875232353806496e-05" />
                <mass value="1.68" />
                <inertia ixx="0.0021147398873455382" ixy="0.0" ixz="0.0" iyy="0.0018129577956607131"
                    iyz="0.0" izz="0.002265435737304666" />
            </inertial>
        </link>
        <joint name="${tf_prefix}rear_left_hip_x" type="revolute">
            <origin xyz="-0.29785 0.05500 0.00000" rpy="0 0 0" />
            <axis xyz="1 0 0" />
            <parent link="${tf_prefix}body" />
            <child link="${tf_prefix}rear_left_hip" />
            <limit effort="1000" velocity="1000.00" lower="-0.78539816339744827899"
                upper="0.78539816339744827899" />
            <!--<dynamics damping="7.0" friction="3.0" /> -->

        </joint>
        <gazebo reference="${tf_prefix}rear_left_hip_x">
            <!-- <kp>10000000.0</kp>
            <kd>50.0</kd> -->
        </gazebo>
        <transmission name="rear_left_hip_x_trans">
            <type>transmission_interface/SimpleTransmission</type>
            <joint name="rear_left_hip_x">
                    <hardwareInterface>hardware_interface/EffortJointInterface</hardwareInterface>
                </joint>
            <actuator name="rear_left_hip_x">
                    <mechanicalReduction>1</mechanicalReduction>
                    <hardwareInterface>hardware_interface/EffortJointInterface</hardwareInterface>
            </actuator>
        </transmission>
        <link name="${tf_prefix}rear_left_upper_leg">
            <visual>
                <geometry>
                    <mesh
                        filename="package://spot_description/meshes/rear_left_upper_leg.dae" />
                </geometry>
            </visual>
            <collision>
                <geometry>
                    <mesh
                        filename="package://spot_description/meshes/rear_left_upper_leg_collision.stl" />
                </geometry>
            </collision>
            <inertial>
                <origin rpy="-0.26437828203369795 -0.04853174570753804 0.024046963096353124"
                    xyz="0.005142373498529196 -0.0024323679972440004 -0.12100915610790253" />
                <mass value="2.34" />
                <inertia ixx="0.02755964961185679" ixy="0.0" ixz="0.0" iyy="0.027354914287651046"
                    iyz="0.0" izz="0.002848145546743553" />
            </inertial>
        </link>
        <joint name="${tf_prefix}rear_left_hip_y" type="revolute">
            <origin xyz="0.0 0.110945 0.0" rpy="0 0 0" />
            <axis xyz="0 1 0" />
            <parent link="${tf_prefix}rear_left_hip" />
            <child link="${tf_prefix}rear_left_upper_leg" />
            <limit effort="1000" velocity="1000.00" lower="-0.89884456477707963539"
                upper="2.2951079663725435509" />
            <!--<dynamics damping="7.0" friction="3.0" /> -->

        </joint>
        <gazebo reference="${tf_prefix}rear_left_hip_y">
            <!-- <kp>10000000.0</kp>
            <kd>50.0</kd> -->
        </gazebo>
        <transmission name="rear_left_hip_y_trans">
            <type>transmission_interface/SimpleTransmission</type>
            <joint name="rear_left_hip_y">
                    <hardwareInterface>hardware_interface/EffortJointInterface</hardwareInterface>
                </joint>
            <actuator name="rear_left_hip_y">
                    <mechanicalReduction>1</mechanicalReduction>
                    <hardwareInterface>hardware_interface/EffortJointInterface</hardwareInterface>
            </actuator>
        </transmission>
        <link name="${tf_prefix}rear_left_lower_leg">
            <visual>
                <geometry>
                    <mesh
                        filename="package://spot_description/meshes/rear_left_lower_leg.dae" />
                </geometry>
            </visual>
            <collision>
                <geometry>
                    <mesh
                        filename="package://spot_description/meshes/rear_left_lower_leg_collision.stl" />
                </geometry>
            </collision>
            <collision>
                <origin xyz="0.0 0.0 -0.3365" rpy="0 0 0" />
                <geometry>
                    <sphere radius="0.036"/>
                </geometry>
            </collision>
            <inertial>
                <origin rpy="-0.007266925694167092 -0.009591807116834161 0.00035255970529224356"
                    xyz="0.00225794012658298 4.607596201822162e-05 -0.1800822913646698" />
                <mass value="0.35" />
                <inertia ixx="0.003999022654901177" ixy="0.0" ixz="0.0" iyy="0.0040503157598010785"
                    iyz="0.0" izz="0.0001493402097647426" />
            </inertial>
        </link>
        <joint name="${tf_prefix}rear_left_knee" type="revolute">
            <origin xyz="0.025 0.000 -0.3205" rpy="0 0 0" />
            <axis xyz="0 1 0" />
            <parent link="${tf_prefix}rear_left_upper_leg" />
            <child link="${tf_prefix}rear_left_lower_leg" />
            <limit effort="1000" velocity="1000.00" lower="-2.7929" upper="-0.267153" />
            <!--<dynamics damping="7.0" friction="3.0" /> -->

        </joint>
        <link name="${tf_prefix}rear_left_ee"/>
        <joint name="${tf_prefix}rear_left_ee" type="fixed">
            <origin xyz="0.000 0.000 -0.37" rpy="0 0 0" />
            <parent link="${tf_prefix}rear_left_lower_leg" />
            <child link="${tf_prefix}rear_left_ee" />
        </joint>

        <gazebo reference="${tf_prefix}rear_left_knee">
            <!-- <kp>10000000.0</kp>
            <kd>50.0</kd> -->
        </gazebo>

        <transmission name="rear_left_knee_trans">
            <type>transmission_interface/SimpleTransmission</type>
            <joint name="rear_left_knee">
                    <hardwareInterface>hardware_interface/EffortJointInterface</hardwareInterface>
                </joint>
            <actuator name="rear_left_knee">
                    <mechanicalReduction>1</mechanicalReduction>
                    <hardwareInterface>hardware_interface/EffortJointInterface</hardwareInterface>
            </actuator>
        </transmission>
        <link name="${tf_prefix}rear_right_hip">
            <visual>
                <geometry>
                    <mesh
                        filename="package://spot_description/meshes/rear_right_hip.dae" />
                </geometry>
            </visual>
            <collision>
                <geometry>
                    <mesh filename="package://spot_description/meshes/rear_right_hip_collision.stl" />
                </geometry>
            </collision>
            <inertial>
                <origin rpy="0.7165213493123055 -0.02956473059648479 0.03655230014702582"
                    xyz="-0.005374345928430557 -0.012841847725212574 -9.875232353806496e-05" />
                <mass value="1.68" />
                <inertia ixx="0.0021147398873455382" ixy="0.0" ixz="0.0" iyy="0.0018129577956607131"
                    iyz="0.0" izz="0.002265435737304666" />
            </inertial>
        </link>
        <joint name="${tf_prefix}rear_right_hip_x" type="revolute">
            <origin xyz="-0.29785 -0.05500 0.00000" rpy="0 0 0" />
            <axis xyz="1 0 0" />
            <parent link="${tf_prefix}body" />
            <child link="${tf_prefix}rear_right_hip" />
            <limit effort="1000" velocity="1000.00" lower="-0.78539816339744827899"
                upper="0.78539816339744827899" />
            <!--<dynamics damping="7.0" friction="3.0" /> -->
        </joint>

        <gazebo reference="${tf_prefix}rear_right_hip_x">
            <!-- <kp>10000000.0</kp>
            <kd>50.0</kd> -->
        </gazebo>

        <transmission name="rear_right_hip_x_trans">
            <type>transmission_interface/SimpleTransmission</type>
            <joint name="rear_right_hip_x">
                    <hardwareInterface>hardware_interface/EffortJointInterface</hardwareInterface>
                </joint>
            <actuator name="rear_right_hip_x">
                    <mechanicalReduction>1</mechanicalReduction>
                    <hardwareInterface>hardware_interface/EffortJointInterface</hardwareInterface>
            </actuator>
        </transmission>
        <link name="${tf_prefix}rear_right_upper_leg">
            <visual>
                <geometry>
                    <mesh
                        filename="package://spot_description/meshes/rear_right_upper_leg.dae" />
                </geometry>
            </visual>
            <collision>
                <geometry>
                    <mesh
                        filename="package://spot_description/meshes/rear_right_upper_leg_collision.stl" />
                </geometry>
            </collision>
            <inertial>
                <origin rpy="0.2643905306958363 -0.04853174688302708 -0.024046943559834943"
                    xyz="0.005142373498529196 0.0024323677644133568 -0.12100915610790253" />
                <mass value="2.34" />
                <inertia ixx="0.02755964678927691" ixy="0.0" ixz="0.0" iyy="0.02735491706466737"
                    iyz="0.0" izz="0.0028481453594764797" />
            </inertial>
        </link>
        <joint name="${tf_prefix}rear_right_hip_y" type="revolute">
            <origin xyz="0.0 -0.110945 0.0" rpy="0 0 0" />
            <axis xyz="0 1 0" />
            <parent link="${tf_prefix}rear_right_hip" />
            <child link="${tf_prefix}rear_right_upper_leg" />
            <limit effort="1000" velocity="1000.00" lower="-0.89884456477707963539"
                upper="2.2951079663725435509" />
            <!--<dynamics damping="7.0" friction="3.0" /> -->
        </joint>
        <gazebo reference="${tf_prefix}rear_right_hip_y">
            <!-- <kp>10000000.0</kp>
            <kd>50.0</kd> -->
        </gazebo>
        <transmission name="rear_right_hip_y_trans">
            <type>transmission_interface/SimpleTransmission</type>
            <joint name="rear_right_hip_y">
                    <hardwareInterface>hardware_interface/EffortJointInterface</hardwareInterface>
                </joint>
            <actuator name="rear_right_hip_y">
                    <mechanicalReduction>1</mechanicalReduction>
                    <hardwareInterface>hardware_interface/EffortJointInterface</hardwareInterface>
            </actuator>
        </transmission>
        <link name="${tf_prefix}rear_right_lower_leg">
            <visual>
                <geometry>
                    <mesh
                        filename="package://spot_description/meshes/rear_right_lower_leg.dae" />
                </geometry>
            </visual>
            <collision>
                <geometry>
                    <mesh
                        filename="package://spot_description/meshes/rear_right_lower_leg_collision.stl" />
                </geometry>
            </collision>
            <collision>
                <origin xyz="0.0 0.0 -0.3365" rpy="0 0 0" />
                <geometry>
                    <sphere radius="0.036"/>
                </geometry>
            </collision>
            <inertial>
                <origin rpy="-0.007266925694167092 -0.009591807116834161 0.00035255970529224356"
                    xyz="0.00225794012658298 4.607596201822162e-05 -0.1800822913646698" />
                <mass value="0.35" />
                <inertia ixx="0.003999022654901177" ixy="0.0" ixz="0.0" iyy="0.0040503157598010785"
                    iyz="0.0" izz="0.0001493402097647426" />
            </inertial>
        </link>
        <joint name="${tf_prefix}rear_right_knee" type="revolute">
            <origin xyz="0.025 0.000 -0.3205" rpy="0 0 0" />
            <axis xyz="0 1 0" />
            <parent link="${tf_prefix}rear_right_upper_leg" />
            <child link="${tf_prefix}rear_right_lower_leg" />
            <limit effort="1000" velocity="1000.00" lower="-2.7929" upper="-0.257725" />
            <!--<dynamics damping="7.0" friction="3.0" /> -->
        </joint>
        <link name="${tf_prefix}rear_right_ee"/>
        <joint name="${tf_prefix}rear_right_ee" type="fixed">
            <origin xyz="0.000 0.000 -0.37" rpy="0 0 0" />
            <parent link="${tf_prefix}rear_right_lower_leg" />
            <child link="${tf_prefix}rear_right_ee" />
        </joint>
        
        <gazebo reference="${tf_prefix}rear_right_knee">
            <!-- <kp>10000000.0</kp>
            <kd>50.0</kd> -->
        </gazebo>


        <transmission name="rear_right_knee_trans">
            <type>transmission_interface/SimpleTransmission</type>
            <joint name="rear_right_knee">
                    <hardwareInterface>hardware_interface/EffortJointInterface</hardwareInterface>
                </joint>
            <actuator name="rear_right_knee">
                    <mechanicalReduction>1</mechanicalReduction>
                    <hardwareInterface>hardware_interface/EffortJointInterface</hardwareInterface>
            </actuator>
        </transmission>

        <gazebo reference="front_left_lower_leg">
            <!-- <sensor name="front_left_lower_leg_contactsensor_sensor" type="contact">
            <always_on>true</always_on>
            <contact>
                <collision>front_left_lower_leg_fixed_joint_lump__front_bump_sensor_collision</collision>
            </contact>
            <plugin filename="libgazebo_ros_bumper.so" name="front_left_lower_leg_plugin">
                <bumperTopicName>front_left_lower_leg_contact</bumperTopicName>
                <frameName>front_left_lower_leg</frameName>
            </plugin>
            </sensor> -->
            <!-- <kp>100000.0</kp>
            <kd>1.0</kd> -->
            <mu1>100.0</mu1>
            <mu2>100.0</mu2>
            <maxVel>0.0</maxVel>
            <minDepth>0.05</minDepth>
            <material>Gazebo/FlatBlack</material>
        </gazebo>
        <gazebo reference="front_right_lower_leg">
            <!-- <sensor name="front_right_lower_leg_contactsensor_sensor" type="contact">
            <always_on>true</always_on>
            <contact>
                <collision>front_right_lower_leg_fixed_joint_lump__front_bump_sensor_collision</collision>
            </contact>
            <plugin filename="libgazebo_ros_bumper.so" name="front_right_lower_leg_plugin">
                <bumperTopicName>front_right_lower_leg_contact</bumperTopicName>
                <frameName>front_right_lower_leg</frameName>
            </plugin>
            </sensor> -->
            <!-- <kp>100000.0</kp>
            <kd>1.0</kd> -->
            <mu1>100.0</mu1>
            <mu2>100.0</mu2>
            <maxVel>0.0</maxVel>
            <minDepth>0.05</minDepth>
            <material>Gazebo/FlatBlack</material>
        </gazebo>

        <gazebo reference="rear_left_lower_leg">
            <!-- <sensor name="rear_left_lower_leg_contactsensor_sensor" type="contact">
            <always_on>true</always_on>
            <contact>
                <collision>rear_left_lower_leg_fixed_joint_lump__rear_bump_sensor_collision</collision>
            </contact>
            <plugin filename="libgazebo_ros_bumper.so" name="rear_left_lower_leg_plugin">
                <bumperTopicName>rear_left_lower_leg_contact</bumperTopicName>
                <frameName>rear_left_lower_leg</frameName>
            </plugin>
            </sensor> -->
            <!-- <kp>100000.0</kp>
            <kd>1.0</kd> -->
            <mu1>100.0</mu1>
            <mu2>100.0</mu2>
            <maxVel>0.0</maxVel>
            <minDepth>0.05</minDepth>
            <material>Gazebo/FlatBlack</material>
        </gazebo>
        <gazebo reference="rear_right_lower_leg">
            <!-- <sensor name="rear_right_lower_leg_contactsensor_sensor" type="contact">
            <always_on>true</always_on>
            <contact>
                <collision>rear_right_lower_leg_fixed_joint_lump__rear_bump_sensor_collision</collision>
            </contact>
            <plugin filename="libgazebo_ros_bumper.so" name="rear_right_lower_leg_plugin">
                <bumperTopicName>rear_right_lower_leg_contact</bumperTopicName>
                <frameName>rear_right_lower_leg</frameName>
            </plugin>
            </sensor> -->
            <!-- <kp>100000.0</kp>
            <kd>1.0</kd> -->
            <mu1>100.0</mu1>
            <mu2>100.0</mu2>
            <maxVel>0.0</maxVel>
            <minDepth>0.05</minDepth>
            <material>Gazebo/FlatBlack</material>
        </gazebo>
        <gazebo>
        <plugin filename="libgazebo_ros_p3d.so" name="p3d_base_controller">
            <alwaysOn>true</alwaysOn>
            <updateRate>10.0</updateRate>
            <bodyName>${tf_prefix}base_link</bodyName>
            <topicName>odom/ground_truth</topicName>
            <gaussianNoise>0.01</gaussianNoise>
            <frameName>world</frameName>
            <xyzOffsets>0 0 0</xyzOffsets>
            <rpyOffsets>0 0 0</rpyOffsets>
            </plugin>
        </gazebo>

        <!-- Standard accessories. -->
        <!-- <xacro:include filename="$(find spot_description)/urdf/accessories.urdf.xacro" /> -->

        <!-- Optional custom includes. -->
        <!-- <xacro:include filename="$(optenv SPOT_URDF_EXTRAS empty.urdf)" /> -->

       
    </xacro:macro>

</robot>