<?xml version="1.0" ?>
<!-- =================================================================================== -->
<!-- |    This document was autogenerated by xacro from /home/sankalp/ws_teleop_spot/src/papras-spot/papras_spot_demo/description/urdf/spot_7dof_teleop.urdf.xacro | -->
<!-- |    EDITING THIS FILE BY HAND IS NOT RECOMMENDED                                 | -->
<!-- =================================================================================== -->
<robot name="papras_7dof_spot_move_teleop">
    <!-- left arm prefix is robot3/ -->
    <!-- right arm prefix is robot4/ -->
    <!-- PAPRAS URDF Macros -->
    <!-- Main URDF File should contain:
        - world link
        - world-env joint
        - env link
        - env-robotn/link1 joint for each mount -->
    <!-- This file contains URDF geometry, transmission data and Gazebo references -->
    <material name="black">
        <color rgba="0.0 0.0 0.0 1.0" />
    </material>
    <material name="blue">
        <color rgba="0.0 0.0 0.8 1.0" />
    </material>
    <material name="green">
        <color rgba="0.0 0.8 0.0 1.0" />
    </material>
    <material name="grey">
        <color rgba="0.5 0.5 0.5 1.0" />
    </material>
    <material name="orange">
        <color rgba="1.0 0.4235294117647059 0.0392156862745098 1.0" />
    </material>
    <material name="brown">
        <color rgba="0.8705882352941177 0.8117647058823529 0.7647058823529411 1.0" />
    </material>
    <material name="red">
        <color rgba="0.8 0.0 0.0 1.0" />
    </material>
    <material name="white">
        <color rgba="1.0 1.0 1.0 1.0" />
    </material>
    <!-- Import all Gazebo-customization elements, including Gazebo colors -->
    <!-- World -->
    <gazebo reference="world">
        <plugin name="gazebo_ros_control">
            <robotNamespace>/</robotNamespace>
        </plugin>
    </gazebo>
    <!-- Evn Link -->
    <gazebo reference="env" />
    <!-- ros_control plugin -->
    <gazebo>
        <plugin filename="libgazebo_ros_control.so" name="gazebo_ros_control">
            <robotSimType>gazebo_ros_control/DefaultRobotHWSim</robotSimType>
        </plugin>
    </gazebo>
    <mujoco>
        <compiler balanceinertia="true" discardvisual="false" meshdir="../assets/" />
    </mujoco>
    <!-- <link name="world"/> -->
    <link name="body">
        <visual>
            <geometry>
                <mesh filename="package://spot_description/meshes/body.dae" />
            </geometry>
        </visual>
        <collision>
            <geometry>
                <mesh filename="package://spot_description/meshes/body_collision.stl" />
            </geometry>
        </collision>
        <inertial>
            <mass value="16.0" />
            <inertia ixx="0.0973333333333" ixy="0.0" ixz="0.0" iyy="1.02466666667" iyz="0.0" izz="1.04493333333" />
            <origin xyz="0 0 0" rpy="0 0 0" />
        </inertial>
        <!-- <inertial>
                <origin rpy="0.0 0.0 0.0"
                    xyz="0.006394396536052227 -9.812158532440662e-05 0.0009113792330026627" />
                <mass value="80.86" />
                <inertia ixx="0.49189833333" ixy="0.0" ixz="0.0" iyy="5.178409"
                    iyz="0.0" izz="5.28083183333" />
            </inertial> -->
    </link>
    <link name="base_link" />
    <joint name="base_link_joint" type="fixed">
        <origin rpy="0 0 0" xyz="0 0 0" />
        <parent link="body" />
        <child link="base_link" />
    </joint>
    <link name="front_rail">
        <!-- <inertial>
                <origin rpy="0. 0. 0." xyz="0. 0. 0." />
                <mass value="1.0e-6" />
                <inertia ixx="1.0e-9" ixy="0.0" ixz="0.0" iyy="1.0e-9" iyz="0.0" izz="1.0e-9" />
            </inertial> -->
    </link>
    <joint name="front_rail_joint" type="fixed">
        <origin rpy="0 0 0" xyz="0.223 0 0.0805" />
        <parent link="body" />
        <child link="front_rail" />
    </joint>
    <link name="rear_rail">
        <!-- <inertial>
                <origin rpy="0. 0. 0." xyz="0. 0. 0." />
                <mass value="1.0e-6" />
                <inertia ixx="1.0e-9" ixy="0.0" ixz="0.0" iyy="1.0e-9" iyz="0.0" izz="1.0e-9" />
            </inertial> -->
    </link>
    <joint name="rear_rail_joint" type="fixed">
        <origin rpy="0 0 0" xyz="-0.223 0 0.0805" />
        <parent link="body" />
        <child link="rear_rail" />
    </joint>
    <link name="front_left_hip">
        <visual>
            <geometry>
                <mesh filename="package://spot_description/meshes/front_left_hip.dae" />
            </geometry>
        </visual>
        <collision>
            <geometry>
                <mesh filename="package://spot_description/meshes/front_left_hip_collision.stl" />
            </geometry>
        </collision>
        <inertial>
            <origin rpy="-0.716521349312305 0.02956473059648479 0.03655230014702582" xyz="-0.005374345928430557 0.012841847725212574 9.875232353806496e-05" />
            <mass value="1.68" />
            <inertia ixx="0.0021147398873455382" ixy="0.0" ixz="0.0" iyy="0.0018129577956607131" iyz="0.0" izz="0.002265435737304666" />
        </inertial>
    </link>
    <joint name="front_left_hip_x" type="revolute">
        <origin rpy="0 0 0" xyz="0.29785 0.05500 0.00000" />
        <axis xyz="1 0 0" />
        <parent link="body" />
        <child link="front_left_hip" />
        <limit effort="1000" lower="-0.78539816339744827899" upper="0.78539816339744827899" velocity="1000.00" />
        <!-- <dynamics damping="7.0" friction="3.0" /> -->
    </joint>
    <gazebo reference="front_left_hip_x">
        <!-- <kp>10000000.0</kp>
            <kd>50.0</kd> -->
    </gazebo>
    <transmission name="front_left_hip_x_trans">
        <type>transmission_interface/SimpleTransmission</type>
        <joint name="front_left_hip_x">
            <hardwareInterface>hardware_interface/EffortJointInterface</hardwareInterface>
        </joint>
        <actuator name="front_left_hip_x">
            <mechanicalReduction>1</mechanicalReduction>
            <hardwareInterface>hardware_interface/EffortJointInterface</hardwareInterface>
        </actuator>
    </transmission>
    <link name="front_left_upper_leg">
        <visual>
            <geometry>
                <mesh filename="package://spot_description/meshes/front_left_upper_leg.dae" />
            </geometry>
        </visual>
        <collision>
            <geometry>
                <mesh filename="package://spot_description/meshes/front_left_upper_leg_collision.stl" />
            </geometry>
        </collision>
        <inertial>
            <origin rpy="-0.26437828203369795 -0.04853174570753804 0.024046963096353124" xyz="0.005142373498529196 -0.0024323679972440004 -0.12100915610790253" />
            <mass value="2.34" />
            <inertia ixx="0.02755964961185679" ixy="0.0" ixz="0.0" iyy="0.027354914287651046" iyz="0.0" izz="0.002848145546743553" />
        </inertial>
    </link>
    <joint name="front_left_hip_y" type="revolute">
        <origin rpy="0 0 0" xyz="0.0 0.110945 0.0" />
        <axis xyz="0 1 0" />
        <parent link="front_left_hip" />
        <child link="front_left_upper_leg" />
        <limit effort="1000" lower="-0.89884456477707963539" upper="2.2951079663725435509" velocity="1000.00" />
        <!--<dynamics damping="7.0" friction="3.0" /> -->
    </joint>
    <gazebo reference="front_left_hip_y">
        <!-- <kp>10000000.0</kp>
            <kd>50.0</kd> -->
    </gazebo>
    <transmission name="front_left_hip_y_trans">
        <type>transmission_interface/SimpleTransmission</type>
        <joint name="front_left_hip_y">
            <hardwareInterface>hardware_interface/EffortJointInterface</hardwareInterface>
        </joint>
        <actuator name="front_left_hip_y">
            <mechanicalReduction>1</mechanicalReduction>
            <hardwareInterface>hardware_interface/EffortJointInterface</hardwareInterface>
        </actuator>
    </transmission>
    <link name="front_left_lower_leg">
        <visual>
            <geometry>
                <mesh filename="package://spot_description/meshes/front_left_lower_leg.dae" />
            </geometry>
        </visual>
        <collision>
            <geometry>
                <mesh filename="package://spot_description/meshes/front_left_lower_leg_collision.stl" />
            </geometry>
        </collision>
        <collision>
            <origin rpy="0 0 0" xyz="0.0 0.0 -0.3365" />
            <geometry>
                <sphere radius="0.036" />
            </geometry>
        </collision>
        <inertial>
            <origin rpy="-0.007266925694167092 -0.009591807116834161 0.00035255970529224356" xyz="0.00225794012658298 4.607596201822162e-05 -0.1800822913646698" />
            <mass value="0.35" />
            <inertia ixx="0.003999022654901177" ixy="0.0" ixz="0.0" iyy="0.0040503157598010785" iyz="0.0" izz="0.0001493402097647426" />
        </inertial>
    </link>
    <joint name="front_left_knee" type="revolute">
        <origin rpy="0 0 0" xyz="0.025 0.000 -0.3205" />
        <axis xyz="0 1 0" />
        <parent link="front_left_upper_leg" />
        <child link="front_left_lower_leg" />
        <limit effort="1000" lower="-2.7929" upper="-0.254801" velocity="1000.00" />
        <!--<dynamics damping="7.0" friction="3.0" /> -->
    </joint>
    <gazebo reference="front_left_knee">
        <!-- <kp>10000000.0</kp>
            <kd>50.0</kd> -->
    </gazebo>
    <link name="front_left_ee" />
    <joint name="front_left_ee" type="fixed">
        <origin rpy="0 0 0" xyz="0.000 0.000 -0.37" />
        <parent link="front_left_lower_leg" />
        <child link="front_left_ee" />
    </joint>
    <transmission name="front_left_knee_trans">
        <type>transmission_interface/SimpleTransmission</type>
        <joint name="front_left_knee">
            <hardwareInterface>hardware_interface/EffortJointInterface</hardwareInterface>
        </joint>
        <actuator name="front_left_knee">
            <mechanicalReduction>1</mechanicalReduction>
            <hardwareInterface>hardware_interface/EffortJointInterface</hardwareInterface>
        </actuator>
    </transmission>
    <link name="front_right_hip">
        <visual>
            <geometry>
                <mesh filename="package://spot_description/meshes/front_right_hip.dae" />
            </geometry>
        </visual>
        <collision>
            <geometry>
                <mesh filename="package://spot_description/meshes/front_right_hip_collision.stl" />
            </geometry>
        </collision>
        <inertial>
            <origin rpy="0.7165213493123055 -0.02956473059648479 0.03655230014702582" xyz="-0.005374345928430557 -0.012841847725212574 -9.875232353806496e-05" />
            <mass value="1.68" />
            <inertia ixx="0.0021147398873455382" ixy="0.0" ixz="0.0" iyy="0.0018129577956607131" iyz="0.0" izz="0.002265435737304666" />
        </inertial>
    </link>
    <joint name="front_right_hip_x" type="revolute">
        <origin rpy="0 0 0" xyz="0.29785 -0.05500 0.00000" />
        <axis xyz="1 0 0" />
        <parent link="body" />
        <child link="front_right_hip" />
        <limit effort="1000" lower="-0.78539816339744827899" upper="0.78539816339744827899" velocity="1000.00" />
        <!--<dynamics damping="7.0" friction="3.0" /> -->
    </joint>
    <gazebo reference="front_right_hip_x">
        <!-- <kp>10000000.0</kp>
            <kd>50.0</kd> -->
    </gazebo>
    <transmission name="front_right_hip_x_trans">
        <type>transmission_interface/SimpleTransmission</type>
        <joint name="front_right_hip_x">
            <hardwareInterface>hardware_interface/EffortJointInterface</hardwareInterface>
        </joint>
        <actuator name="front_right_hip_x">
            <mechanicalReduction>1</mechanicalReduction>
            <hardwareInterface>hardware_interface/EffortJointInterface</hardwareInterface>
        </actuator>
    </transmission>
    <link name="front_right_upper_leg">
        <visual>
            <geometry>
                <mesh filename="package://spot_description/meshes/front_right_upper_leg.dae" />
            </geometry>
        </visual>
        <collision>
            <geometry>
                <mesh filename="package://spot_description/meshes/front_right_upper_leg_collision.stl" />
            </geometry>
        </collision>
        <inertial>
            <origin rpy="0.2643905306958363 -0.04853174688302708 -0.024046943559834943" xyz="0.005142373498529196 0.0024323677644133568 -0.12100915610790253" />
            <mass value="2.34" />
            <inertia ixx="0.02755964678927691" ixy="0.0" ixz="0.0" iyy="0.02735491706466737" iyz="0.0" izz="0.0028481453594764797" />
        </inertial>
    </link>
    <joint name="front_right_hip_y" type="revolute">
        <origin rpy="0 0 0" xyz="0.0 -0.110945 0.0" />
        <axis xyz="0 1 0" />
        <parent link="front_right_hip" />
        <child link="front_right_upper_leg" />
        <limit effort="1000" lower="-0.89884456477707963539" upper="2.2951079663725435509" velocity="1000.00" />
        <!--<dynamics damping="7.0" friction="3.0" /> -->
    </joint>
    <link name="front_right_ee" />
    <joint name="front_right_ee" type="fixed">
        <origin rpy="0 0 0" xyz="0.000 0.000 -0.37" />
        <parent link="front_right_lower_leg" />
        <child link="front_right_ee" />
    </joint>
    <gazebo reference="front_right_hip_y">
        <!-- <kp>10000000.0</kp>
            <kd>50.0</kd> -->
    </gazebo>
    <transmission name="front_right_hip_y_trans">
        <type>transmission_interface/SimpleTransmission</type>
        <joint name="front_right_hip_y">
            <hardwareInterface>hardware_interface/EffortJointInterface</hardwareInterface>
        </joint>
        <actuator name="front_right_hip_y">
            <mechanicalReduction>1</mechanicalReduction>
            <hardwareInterface>hardware_interface/EffortJointInterface</hardwareInterface>
        </actuator>
    </transmission>
    <link name="front_right_lower_leg">
        <visual>
            <geometry>
                <mesh filename="package://spot_description/meshes/front_right_lower_leg.dae" />
            </geometry>
        </visual>
        <collision>
            <geometry>
                <mesh filename="package://spot_description/meshes/front_right_lower_leg_collision.stl" />
            </geometry>
        </collision>
        <collision>
            <origin rpy="0 0 0" xyz="0.0 0.0 -0.3365" />
            <geometry>
                <sphere radius="0.036" />
            </geometry>
        </collision>
        <inertial>
            <origin rpy="-0.007266925694167092 -0.009591807116834161 0.00035255970529224356" xyz="0.00225794012658298 4.607596201822162e-05 -0.1800822913646698" />
            <mass value="0.35" />
            <inertia ixx="0.003999022654901177" ixy="0.0" ixz="0.0" iyy="0.0040503157598010785" iyz="0.0" izz="0.0001493402097647426" />
        </inertial>
    </link>
    <joint name="front_right_knee" type="revolute">
        <origin rpy="0 0 0" xyz="0.025 0.000 -0.3205" />
        <axis xyz="0 1 0" />
        <parent link="front_right_upper_leg" />
        <child link="front_right_lower_leg" />
        <limit effort="1000" lower="-2.7929" upper="-0.247563" velocity="1000.00" />
        <!--<dynamics damping="7.0" friction="3.0" /> -->
    </joint>
    <gazebo reference="front_right_knee">
        <!-- <kp>10000000.0</kp>
            <kd>50.0</kd> -->
    </gazebo>
    <transmission name="front_right_knee_trans">
        <type>transmission_interface/SimpleTransmission</type>
        <joint name="front_right_knee">
            <hardwareInterface>hardware_interface/EffortJointInterface</hardwareInterface>
        </joint>
        <actuator name="front_right_knee">
            <mechanicalReduction>1</mechanicalReduction>
            <hardwareInterface>hardware_interface/EffortJointInterface</hardwareInterface>
        </actuator>
    </transmission>
    <link name="rear_left_hip">
        <visual>
            <geometry>
                <mesh filename="package://spot_description/meshes/rear_left_hip.dae" />
            </geometry>
        </visual>
        <collision>
            <geometry>
                <mesh filename="package://spot_description/meshes/rear_left_hip_collision.stl" />
            </geometry>
        </collision>
        <inertial>
            <origin rpy="0.7165213493123055 -0.02956473059648479 0.03655230014702582" xyz="-0.005374345928430557 -0.012841847725212574 -9.875232353806496e-05" />
            <mass value="1.68" />
            <inertia ixx="0.0021147398873455382" ixy="0.0" ixz="0.0" iyy="0.0018129577956607131" iyz="0.0" izz="0.002265435737304666" />
        </inertial>
    </link>
    <joint name="rear_left_hip_x" type="revolute">
        <origin rpy="0 0 0" xyz="-0.29785 0.05500 0.00000" />
        <axis xyz="1 0 0" />
        <parent link="body" />
        <child link="rear_left_hip" />
        <limit effort="1000" lower="-0.78539816339744827899" upper="0.78539816339744827899" velocity="1000.00" />
        <!--<dynamics damping="7.0" friction="3.0" /> -->
    </joint>
    <gazebo reference="rear_left_hip_x">
        <!-- <kp>10000000.0</kp>
            <kd>50.0</kd> -->
    </gazebo>
    <transmission name="rear_left_hip_x_trans">
        <type>transmission_interface/SimpleTransmission</type>
        <joint name="rear_left_hip_x">
            <hardwareInterface>hardware_interface/EffortJointInterface</hardwareInterface>
        </joint>
        <actuator name="rear_left_hip_x">
            <mechanicalReduction>1</mechanicalReduction>
            <hardwareInterface>hardware_interface/EffortJointInterface</hardwareInterface>
        </actuator>
    </transmission>
    <link name="rear_left_upper_leg">
        <visual>
            <geometry>
                <mesh filename="package://spot_description/meshes/rear_left_upper_leg.dae" />
            </geometry>
        </visual>
        <collision>
            <geometry>
                <mesh filename="package://spot_description/meshes/rear_left_upper_leg_collision.stl" />
            </geometry>
        </collision>
        <inertial>
            <origin rpy="-0.26437828203369795 -0.04853174570753804 0.024046963096353124" xyz="0.005142373498529196 -0.0024323679972440004 -0.12100915610790253" />
            <mass value="2.34" />
            <inertia ixx="0.02755964961185679" ixy="0.0" ixz="0.0" iyy="0.027354914287651046" iyz="0.0" izz="0.002848145546743553" />
        </inertial>
    </link>
    <joint name="rear_left_hip_y" type="revolute">
        <origin rpy="0 0 0" xyz="0.0 0.110945 0.0" />
        <axis xyz="0 1 0" />
        <parent link="rear_left_hip" />
        <child link="rear_left_upper_leg" />
        <limit effort="1000" lower="-0.89884456477707963539" upper="2.2951079663725435509" velocity="1000.00" />
        <!--<dynamics damping="7.0" friction="3.0" /> -->
    </joint>
    <gazebo reference="rear_left_hip_y">
        <!-- <kp>10000000.0</kp>
            <kd>50.0</kd> -->
    </gazebo>
    <transmission name="rear_left_hip_y_trans">
        <type>transmission_interface/SimpleTransmission</type>
        <joint name="rear_left_hip_y">
            <hardwareInterface>hardware_interface/EffortJointInterface</hardwareInterface>
        </joint>
        <actuator name="rear_left_hip_y">
            <mechanicalReduction>1</mechanicalReduction>
            <hardwareInterface>hardware_interface/EffortJointInterface</hardwareInterface>
        </actuator>
    </transmission>
    <link name="rear_left_lower_leg">
        <visual>
            <geometry>
                <mesh filename="package://spot_description/meshes/rear_left_lower_leg.dae" />
            </geometry>
        </visual>
        <collision>
            <geometry>
                <mesh filename="package://spot_description/meshes/rear_left_lower_leg_collision.stl" />
            </geometry>
        </collision>
        <collision>
            <origin rpy="0 0 0" xyz="0.0 0.0 -0.3365" />
            <geometry>
                <sphere radius="0.036" />
            </geometry>
        </collision>
        <inertial>
            <origin rpy="-0.007266925694167092 -0.009591807116834161 0.00035255970529224356" xyz="0.00225794012658298 4.607596201822162e-05 -0.1800822913646698" />
            <mass value="0.35" />
            <inertia ixx="0.003999022654901177" ixy="0.0" ixz="0.0" iyy="0.0040503157598010785" iyz="0.0" izz="0.0001493402097647426" />
        </inertial>
    </link>
    <joint name="rear_left_knee" type="revolute">
        <origin rpy="0 0 0" xyz="0.025 0.000 -0.3205" />
        <axis xyz="0 1 0" />
        <parent link="rear_left_upper_leg" />
        <child link="rear_left_lower_leg" />
        <limit effort="1000" lower="-2.7929" upper="-0.267153" velocity="1000.00" />
        <!--<dynamics damping="7.0" friction="3.0" /> -->
    </joint>
    <link name="rear_left_ee" />
    <joint name="rear_left_ee" type="fixed">
        <origin rpy="0 0 0" xyz="0.000 0.000 -0.37" />
        <parent link="rear_left_lower_leg" />
        <child link="rear_left_ee" />
    </joint>
    <gazebo reference="rear_left_knee">
        <!-- <kp>10000000.0</kp>
            <kd>50.0</kd> -->
    </gazebo>
    <transmission name="rear_left_knee_trans">
        <type>transmission_interface/SimpleTransmission</type>
        <joint name="rear_left_knee">
            <hardwareInterface>hardware_interface/EffortJointInterface</hardwareInterface>
        </joint>
        <actuator name="rear_left_knee">
            <mechanicalReduction>1</mechanicalReduction>
            <hardwareInterface>hardware_interface/EffortJointInterface</hardwareInterface>
        </actuator>
    </transmission>
    <link name="rear_right_hip">
        <visual>
            <geometry>
                <mesh filename="package://spot_description/meshes/rear_right_hip.dae" />
            </geometry>
        </visual>
        <collision>
            <geometry>
                <mesh filename="package://spot_description/meshes/rear_right_hip_collision.stl" />
            </geometry>
        </collision>
        <inertial>
            <origin rpy="0.7165213493123055 -0.02956473059648479 0.03655230014702582" xyz="-0.005374345928430557 -0.012841847725212574 -9.875232353806496e-05" />
            <mass value="1.68" />
            <inertia ixx="0.0021147398873455382" ixy="0.0" ixz="0.0" iyy="0.0018129577956607131" iyz="0.0" izz="0.002265435737304666" />
        </inertial>
    </link>
    <joint name="rear_right_hip_x" type="revolute">
        <origin rpy="0 0 0" xyz="-0.29785 -0.05500 0.00000" />
        <axis xyz="1 0 0" />
        <parent link="body" />
        <child link="rear_right_hip" />
        <limit effort="1000" lower="-0.78539816339744827899" upper="0.78539816339744827899" velocity="1000.00" />
        <!--<dynamics damping="7.0" friction="3.0" /> -->
    </joint>
    <gazebo reference="rear_right_hip_x">
        <!-- <kp>10000000.0</kp>
            <kd>50.0</kd> -->
    </gazebo>
    <transmission name="rear_right_hip_x_trans">
        <type>transmission_interface/SimpleTransmission</type>
        <joint name="rear_right_hip_x">
            <hardwareInterface>hardware_interface/EffortJointInterface</hardwareInterface>
        </joint>
        <actuator name="rear_right_hip_x">
            <mechanicalReduction>1</mechanicalReduction>
            <hardwareInterface>hardware_interface/EffortJointInterface</hardwareInterface>
        </actuator>
    </transmission>
    <link name="rear_right_upper_leg">
        <visual>
            <geometry>
                <mesh filename="package://spot_description/meshes/rear_right_upper_leg.dae" />
            </geometry>
        </visual>
        <collision>
            <geometry>
                <mesh filename="package://spot_description/meshes/rear_right_upper_leg_collision.stl" />
            </geometry>
        </collision>
        <inertial>
            <origin rpy="0.2643905306958363 -0.04853174688302708 -0.024046943559834943" xyz="0.005142373498529196 0.0024323677644133568 -0.12100915610790253" />
            <mass value="2.34" />
            <inertia ixx="0.02755964678927691" ixy="0.0" ixz="0.0" iyy="0.02735491706466737" iyz="0.0" izz="0.0028481453594764797" />
        </inertial>
    </link>
    <joint name="rear_right_hip_y" type="revolute">
        <origin rpy="0 0 0" xyz="0.0 -0.110945 0.0" />
        <axis xyz="0 1 0" />
        <parent link="rear_right_hip" />
        <child link="rear_right_upper_leg" />
        <limit effort="1000" lower="-0.89884456477707963539" upper="2.2951079663725435509" velocity="1000.00" />
        <!--<dynamics damping="7.0" friction="3.0" /> -->
    </joint>
    <gazebo reference="rear_right_hip_y">
        <!-- <kp>10000000.0</kp>
            <kd>50.0</kd> -->
    </gazebo>
    <transmission name="rear_right_hip_y_trans">
        <type>transmission_interface/SimpleTransmission</type>
        <joint name="rear_right_hip_y">
            <hardwareInterface>hardware_interface/EffortJointInterface</hardwareInterface>
        </joint>
        <actuator name="rear_right_hip_y">
            <mechanicalReduction>1</mechanicalReduction>
            <hardwareInterface>hardware_interface/EffortJointInterface</hardwareInterface>
        </actuator>
    </transmission>
    <link name="rear_right_lower_leg">
        <visual>
            <geometry>
                <mesh filename="package://spot_description/meshes/rear_right_lower_leg.dae" />
            </geometry>
        </visual>
        <collision>
            <geometry>
                <mesh filename="package://spot_description/meshes/rear_right_lower_leg_collision.stl" />
            </geometry>
        </collision>
        <collision>
            <origin rpy="0 0 0" xyz="0.0 0.0 -0.3365" />
            <geometry>
                <sphere radius="0.036" />
            </geometry>
        </collision>
        <inertial>
            <origin rpy="-0.007266925694167092 -0.009591807116834161 0.00035255970529224356" xyz="0.00225794012658298 4.607596201822162e-05 -0.1800822913646698" />
            <mass value="0.35" />
            <inertia ixx="0.003999022654901177" ixy="0.0" ixz="0.0" iyy="0.0040503157598010785" iyz="0.0" izz="0.0001493402097647426" />
        </inertial>
    </link>
    <joint name="rear_right_knee" type="revolute">
        <origin rpy="0 0 0" xyz="0.025 0.000 -0.3205" />
        <axis xyz="0 1 0" />
        <parent link="rear_right_upper_leg" />
        <child link="rear_right_lower_leg" />
        <limit effort="1000" lower="-2.7929" upper="-0.257725" velocity="1000.00" />
        <!--<dynamics damping="7.0" friction="3.0" /> -->
    </joint>
    <link name="rear_right_ee" />
    <joint name="rear_right_ee" type="fixed">
        <origin rpy="0 0 0" xyz="0.000 0.000 -0.37" />
        <parent link="rear_right_lower_leg" />
        <child link="rear_right_ee" />
    </joint>
    <gazebo reference="rear_right_knee">
        <!-- <kp>10000000.0</kp>
            <kd>50.0</kd> -->
    </gazebo>
    <transmission name="rear_right_knee_trans">
        <type>transmission_interface/SimpleTransmission</type>
        <joint name="rear_right_knee">
            <hardwareInterface>hardware_interface/EffortJointInterface</hardwareInterface>
        </joint>
        <actuator name="rear_right_knee">
            <mechanicalReduction>1</mechanicalReduction>
            <hardwareInterface>hardware_interface/EffortJointInterface</hardwareInterface>
        </actuator>
    </transmission>
    <gazebo reference="front_left_lower_leg">
        <!-- <sensor name="front_left_lower_leg_contactsensor_sensor" type="contact">
            <always_on>true</always_on>
            <contact>
                <collision>front_left_lower_leg_fixed_joint_lump__front_bump_sensor_collision</collision>
            </contact>
            <plugin filename="libgazebo_ros_bumper.so" name="front_left_lower_leg_plugin">
                <bumperTopicName>front_left_lower_leg_contact</bumperTopicName>
                <frameName>front_left_lower_leg</frameName>
            </plugin>
            </sensor> -->
        <!-- <kp>100000.0</kp>
            <kd>1.0</kd> -->
        <mu1>100.0</mu1>
        <mu2>100.0</mu2>
        <maxVel>0.0</maxVel>
        <minDepth>0.05</minDepth>
        <material>Gazebo/FlatBlack</material>
    </gazebo>
    <gazebo reference="front_right_lower_leg">
        <!-- <sensor name="front_right_lower_leg_contactsensor_sensor" type="contact">
            <always_on>true</always_on>
            <contact>
                <collision>front_right_lower_leg_fixed_joint_lump__front_bump_sensor_collision</collision>
            </contact>
            <plugin filename="libgazebo_ros_bumper.so" name="front_right_lower_leg_plugin">
                <bumperTopicName>front_right_lower_leg_contact</bumperTopicName>
                <frameName>front_right_lower_leg</frameName>
            </plugin>
            </sensor> -->
        <!-- <kp>100000.0</kp>
            <kd>1.0</kd> -->
        <mu1>100.0</mu1>
        <mu2>100.0</mu2>
        <maxVel>0.0</maxVel>
        <minDepth>0.05</minDepth>
        <material>Gazebo/FlatBlack</material>
    </gazebo>
    <gazebo reference="rear_left_lower_leg">
        <!-- <sensor name="rear_left_lower_leg_contactsensor_sensor" type="contact">
            <always_on>true</always_on>
            <contact>
                <collision>rear_left_lower_leg_fixed_joint_lump__rear_bump_sensor_collision</collision>
            </contact>
            <plugin filename="libgazebo_ros_bumper.so" name="rear_left_lower_leg_plugin">
                <bumperTopicName>rear_left_lower_leg_contact</bumperTopicName>
                <frameName>rear_left_lower_leg</frameName>
            </plugin>
            </sensor> -->
        <!-- <kp>100000.0</kp>
            <kd>1.0</kd> -->
        <mu1>100.0</mu1>
        <mu2>100.0</mu2>
        <maxVel>0.0</maxVel>
        <minDepth>0.05</minDepth>
        <material>Gazebo/FlatBlack</material>
    </gazebo>
    <gazebo reference="rear_right_lower_leg">
        <!-- <sensor name="rear_right_lower_leg_contactsensor_sensor" type="contact">
            <always_on>true</always_on>
            <contact>
                <collision>rear_right_lower_leg_fixed_joint_lump__rear_bump_sensor_collision</collision>
            </contact>
            <plugin filename="libgazebo_ros_bumper.so" name="rear_right_lower_leg_plugin">
                <bumperTopicName>rear_right_lower_leg_contact</bumperTopicName>
                <frameName>rear_right_lower_leg</frameName>
            </plugin>
            </sensor> -->
        <!-- <kp>100000.0</kp>
            <kd>1.0</kd> -->
        <mu1>100.0</mu1>
        <mu2>100.0</mu2>
        <maxVel>0.0</maxVel>
        <minDepth>0.05</minDepth>
        <material>Gazebo/FlatBlack</material>
    </gazebo>
    <gazebo>
        <plugin filename="libgazebo_ros_p3d.so" name="p3d_base_controller">
            <alwaysOn>true</alwaysOn>
            <updateRate>10.0</updateRate>
            <bodyName>base_link</bodyName>
            <topicName>odom/ground_truth</topicName>
            <gaussianNoise>0.01</gaussianNoise>
            <frameName>world</frameName>
            <xyzOffsets>0 0 0</xyzOffsets>
            <rpyOffsets>0 0 0</rpyOffsets>
        </plugin>
    </gazebo>
    <!-- Standard accessories. -->
    <!-- <xacro:include filename="$(find spot_description)/urdf/accessories.urdf.xacro" /> -->
    <!-- Optional custom includes. -->
    <!-- <xacro:include filename="$(optenv SPOT_URDF_EXTRAS empty.urdf)" /> -->
    <joint name="mount_fixed" type="fixed">
        <parent link="front_rail" />
        <child link="env" />
        <origin rpy="0 0 0" xyz="0.09 0 0" />
    </joint>
    <link name="env">
        <visual>
            <origin rpy="0 0 0" xyz="0.0 0.0 0.0" />
            <geometry>
                <mesh filename="package://papras_spot_demo/description/meshes/spot_mount.stl" />
            </geometry>
            <material name="grey" />
        </visual>
        <collision>
            <origin rpy="0 0 0" xyz="0.0 0.0 0.0" />
            <geometry>
                <mesh filename="package://papras_spot_demo/description/meshes/spot_mount.stl" />
            </geometry>
        </collision>
        <inertial>
            <mass value="0.1" />
            <origin xyz="0 0 0" rpy="0 0 0" />
            <inertia ixx="0.03" iyy="0.03" izz="0.03" ixy="0.0" ixz="0.0" iyz="0.0" />
        </inertial>
    </link>
    <gazebo reference="env">
        <self_collide>0</self_collide>
    </gazebo>
    <joint name="robot3/env_arm_fixed" type="fixed">
        <parent link="env" />
        <child link="robot3/link1" />
        <origin rpy="0 -0.7853981633974483 4.71238898038469" xyz="0.0 0.05049 0.09003" />
    </joint>
    <joint name="robot4/env_arm_fixed" type="fixed">
        <parent link="env" />
        <child link="robot4/link1" />
        <origin rpy="0 -0.7853981633974483 1.5707963267948966" xyz="0.0 -0.05049 0.09003" />
    </joint>
    <!-- link 1 -->
    <link name="robot3/link1">
        <visual>
            <origin rpy="0 0 0" xyz="0 0 0" />
            <geometry>
                <mesh filename="package://papras_description/meshes/link1.stl" scale="0.001 0.001 0.001" />
            </geometry>
            <material name="grey" />
        </visual>
        <collision>
            <origin rpy="0 0 0" xyz="0 0 0" />
            <geometry>
                <mesh filename="package://papras_description/meshes/link1.stl" scale="0.001 0.001 0.001" />
            </geometry>
        </collision>
        <inertial>
            <origin rpy="0 0 0" xyz="0.00023 0.00000 0.06223" />
            <mass value="0.85644" />
            <!-- <inertia ixx="1.0" ixy="0.0" ixz="0.0" iyy="1.0" iyz="0.0" izz="1.0" /> -->
            <inertia ixx="0.00121064" ixy="0.0" ixz="0.00001100" iyy="0.00120886" iyz="0.0" izz="0.00038103" />
        </inertial>
    </link>
    <gazebo reference="robot3/link1">
        <kp>1000000.0</kp>
        <kd>100.0</kd>
        <mu1>30.0</mu1>
        <mu2>30.0</mu2>
        <maxVel>1.0</maxVel>
        <minDepth>0.001</minDepth>
        <material>Gazebo/White</material>
        <selfCollide>1</selfCollide>
        <dampingFactor>0.01</dampingFactor>
    </gazebo>
    <!-- Joint 1 -->
    <joint name="robot3/joint1" type="revolute">
        <parent link="robot3/link1" />
        <child link="robot3/link2" />
        <origin rpy="0 0 0" xyz="0.0 0.0 0.126" />
        <axis xyz="0 0 1" />
        <limit effort="100" lower="-3.141592653589793" upper="3.141592653589793" velocity="3.03687" />
        <dynamics damping="0.7" />
    </joint>
    <transmission name="robot3/tran1">
        <type>transmission_interface/SimpleTransmission</type>
        <joint name="robot3/joint1">
            <hardwareInterface>hardware_interface/PositionJointInterface</hardwareInterface>
        </joint>
        <actuator name="robot3/motor1">
            <mechanicalReduction>1</mechanicalReduction>
            <hardwareInterface>hardware_interface/PositionJointInterface</hardwareInterface>
        </actuator>
    </transmission>
    <!-- link 2 -->
    <link name="robot3/link2">
        <visual>
            <origin rpy="0 0 0" xyz="0 0 0" />
            <geometry>
                <mesh filename="package://papras_description/meshes/link2.stl" scale="0.001 0.001 0.001" />
            </geometry>
            <material name="grey" />
        </visual>
        <collision>
            <origin rpy="0 0 0" xyz="0 0 0" />
            <geometry>
                <mesh filename="package://papras_description/meshes/link2.stl" scale="0.001 0.001 0.001" />
            </geometry>
        </collision>
        <inertial>
            <origin rpy="0 0 0" xyz="0.00000 0.00080 0.03183" />
            <!--<origin xyz="0.00000 -0.06820 -0.00117" rpy="0 0 0"/>-->
            <mass value="0.94658" />
            <inertia ixx="1.0" ixy="0.0" ixz="0.0" iyy="1.0" iyz="0.0" izz="1.0" />
            <!--<inertia ixx="0.00152547" ixy="0.0" ixz="0.0" iyy="0.00045954" iyz="-0.00001086" izz="0.00151740" />-->
        </inertial>
    </link>
    <gazebo reference="robot3/link2">
        <kp>1000000.0</kp>
        <kd>100.0</kd>
        <mu1>30.0</mu1>
        <mu2>30.0</mu2>
        <maxVel>1.0</maxVel>
        <minDepth>0.001</minDepth>
        <material>Gazebo/White</material>
        <selfCollide>1</selfCollide>
        <dampingFactor>0.01</dampingFactor>
    </gazebo>
    <!-- Joint 2 -->
    <joint name="robot3/joint2" type="revolute">
        <parent link="robot3/link2" />
        <child link="robot3/link3" />
        <origin rpy="1.5707963267948966 -1.5707963267948966 0" xyz="0.0 0.00 0.033" />
        <axis xyz="0 0 1" />
        <limit effort="100" lower="-2.0" upper="2.0" velocity="3.03687" />
        <dynamics damping="0.7" />
    </joint>
    <transmission name="robot3/tran2">
        <type>transmission_interface/SimpleTransmission</type>
        <joint name="robot3/joint2">
            <hardwareInterface>hardware_interface/PositionJointInterface</hardwareInterface>
        </joint>
        <actuator name="robot3/motor2">
            <mechanicalReduction>1</mechanicalReduction>
            <hardwareInterface>hardware_interface/PositionJointInterface</hardwareInterface>
        </actuator>
    </transmission>
    <!-- link 2 -->
    <link name="robot3/link3">
        <visual>
            <origin rpy="0 0 0" xyz="0.0 0.0 0.0" />
            <geometry>
                <mesh filename="package://papras_description/meshes/7dof/link3.stl" />
            </geometry>
            <material name="grey" />
        </visual>
        <collision>
            <origin rpy="0 0 0" xyz="0 0 0" />
            <geometry>
                <mesh filename="package://papras_description/meshes/7dof/link3.stl" />
            </geometry>
        </collision>
        <inertial>
            <origin rpy="0 0 0" xyz="0.00000 0.00080 0.03183" />
            <!--<origin xyz="0.00000 -0.06820 -0.00117" rpy="0 0 0"/>-->
            <mass value="0.49982" />
            <!-- <inertia ixx="1.0" ixy="0.0" ixz="0.0" iyy="1.0" iyz="0.0" izz="1.0" /> -->
            <inertia ixx="0.00078817" ixy="6.3729E-09" ixz="-1.0998E-05" iyy="0.0012133" iyz="-7.0637E-09" izz="0.00073746" />
        </inertial>
    </link>
    <gazebo reference="robot3/link3">
        <kp>1000000.0</kp>
        <kd>100.0</kd>
        <mu1>30.0</mu1>
        <mu2>30.0</mu2>
        <maxVel>1.0</maxVel>
        <minDepth>0.001</minDepth>
        <material>Gazebo/White</material>
        <selfCollide>1</selfCollide>
        <dampingFactor>0.01</dampingFactor>
    </gazebo>
    <!-- Joint 2 -->
    <joint name="robot3/joint3" type="revolute">
        <parent link="robot3/link3" />
        <child link="robot3/link4" />
        <origin rpy="0 -1.5707963267948966 -1.5707963267948966" xyz="0.156382198147594 0 0.000400000000010851" />
        <axis xyz="0 1 0" />
        <limit effort="100" lower="-3.141592653589793" upper="3.141592653589793" velocity="3.03687" />
        <dynamics damping="0.7" />
    </joint>
    <transmission name="robot3/tran3">
        <type>transmission_interface/SimpleTransmission</type>
        <joint name="robot3/joint3">
            <hardwareInterface>hardware_interface/PositionJointInterface</hardwareInterface>
        </joint>
        <actuator name="robot3/motor3">
            <mechanicalReduction>1</mechanicalReduction>
            <hardwareInterface>hardware_interface/PositionJointInterface</hardwareInterface>
        </actuator>
    </transmission>
    <!-- link 2 -->
    <link name="robot3/link4">
        <visual>
            <origin rpy="0 0 0" xyz="0.0 0.0 0.0" />
            <geometry>
                <mesh filename="package://papras_description/meshes/7dof/link4.stl" />
            </geometry>
            <material name="grey" />
        </visual>
        <collision>
            <origin rpy="0 0 0" xyz="0 0 0" />
            <geometry>
                <mesh filename="package://papras_description/meshes/7dof/link4.stl" />
            </geometry>
        </collision>
        <inertial>
            <origin rpy="0 0 0" xyz="-4.86609203880829E-06 0.120506252053841 -0.0279123104678896" />
            <mass value="0.597399042150493" />
            <!-- <inertia ixx="1.0" ixy="0.0" ixz="0.0" iyy="1.0" iyz="0.0" izz="1.0" /> -->
            <inertia ixx="0.0015528567154149" ixy="1.16567414120262E-05" ixz="-2.90009974781987E-06" iyy="0.00077263780701987" iyz="9.95380938833158E-05" izz="0.0018580466481516" />
        </inertial>
    </link>
    <gazebo reference="robot3/link4">
        <kp>1000000.0</kp>
        <kd>100.0</kd>
        <mu1>30.0</mu1>
        <mu2>30.0</mu2>
        <maxVel>1.0</maxVel>
        <minDepth>0.001</minDepth>
        <material>Gazebo/White</material>
        <selfCollide>1</selfCollide>
        <dampingFactor>0.01</dampingFactor>
    </gazebo>
    <!-- Joint 3 -->
    <joint name="robot3/joint4" type="revolute">
        <parent link="robot3/link4" />
        <child link="robot3/link5" />
        <origin rpy="3.141592653589793 -1.5707963267948966 1.5707963267948966" xyz="0.0575 0.10761780185239 0.0300000000000553" />
        <axis xyz="0 1 0" />
        <limit effort="100" lower="-3.141592653589793" upper="1.42" velocity="3.03687" />
        <dynamics damping="0.7" />
    </joint>
    <transmission name="robot3/tran4">
        <type>transmission_interface/SimpleTransmission</type>
        <joint name="robot3/joint4">
            <hardwareInterface>hardware_interface/PositionJointInterface</hardwareInterface>
        </joint>
        <actuator name="robot3/motor4">
            <mechanicalReduction>1</mechanicalReduction>
            <hardwareInterface>hardware_interface/PositionJointInterface</hardwareInterface>
        </actuator>
    </transmission>
    <!-- link 5 -->
    <link name="robot3/link5">
        <visual>
            <origin rpy="0 0 3.14" xyz="0.227 0.0085 -0.024" />
            <geometry>
                <mesh filename="package://papras_description/meshes/link4_papras.stl" scale="0.001 0.001 0.001" />
            </geometry>
            <material name="grey" />
        </visual>
        <collision>
            <origin rpy="0 0 3.14" xyz="0.227 0.0085 -0.024" />
            <geometry>
                <mesh filename="package://papras_description/meshes/link4_papras_simple.stl" scale="0.001 0.001 0.001" />
            </geometry>
        </collision>
        <inertial>
            <origin rpy="0 0 0" xyz="0.12475 -0.05716 0.02979" />
            <!--<origin xyz="-0.07025 0.00034 -0.00021" rpy="0 0 0"/>-->
            <mass value="1.15977" />
            <inertia ixx="1.0" ixy="0.0" ixz="0.0" iyy="1.0" iyz="0.0" izz="1.0" />
            <!--<inertia ixx="0.00096726" ixy="0.00004383" ixz="-0.00002771" iyy="0.00318801" iyz="0.00000627" izz="0.00341484" />-->
        </inertial>
    </link>
    <gazebo reference="robot3/link5">
        <kp>1000000.0</kp>
        <kd>100.0</kd>
        <mu1>30.0</mu1>
        <mu2>30.0</mu2>
        <maxVel>1.0</maxVel>
        <minDepth>0.001</minDepth>
        <material>Gazebo/White</material>
        <selfCollide>1</selfCollide>
        <dampingFactor>0.01</dampingFactor>
    </gazebo>
    <!-- Joint 4 -->
    <joint name="robot3/joint5" type="revolute">
        <parent link="robot3/link5" />
        <child link="robot3/link6" />
        <origin rpy="0 0 0" xyz="0.19500 -0.05750 0.03000" />
        <axis xyz="1 0 0" />
        <limit effort="100" lower="-2.748893571891069" upper="2.748893571891069" velocity="3.03687" />
        <dynamics damping="0.7" />
    </joint>
    <transmission name="robot3/tran5">
        <type>transmission_interface/SimpleTransmission</type>
        <joint name="robot3/joint5">
            <hardwareInterface>hardware_interface/PositionJointInterface</hardwareInterface>
        </joint>
        <actuator name="robot3/motor5">
            <mechanicalReduction>1</mechanicalReduction>
            <hardwareInterface>hardware_interface/PositionJointInterface</hardwareInterface>
        </actuator>
    </transmission>
    <!-- link 6 -->
    <link name="robot3/link6">
        <visual>
            <origin rpy="0 0 0" xyz="0 0 0" />
            <geometry>
                <mesh filename="package://papras_description/meshes/link5.stl" scale="0.001 0.001 0.001" />
            </geometry>
            <material name="grey" />
        </visual>
        <collision>
            <origin rpy="0 0 0" xyz="0 0 0" />
            <geometry>
                <mesh filename="package://papras_description/meshes/link5.stl" scale="0.001 0.001 0.001" />
            </geometry>
        </collision>
        <inertial>
            <origin rpy="0 0 0" xyz="0.05642 -0.00217 0.00002" />
            <!--<origin xyz="-0.00658 -0.04717 0.00002" rpy="0 0 0"/>-->
            <mass value="0.44688" />
            <inertia ixx="1.0" ixy="0.0" ixz="0.0" iyy="1.0" iyz="0.0" izz="1.0" />
            <!--<inertia ixx="0.00030285" ixy="0.00000761" ixz="0.00000031" iyy="0.00022339" iyz="-0.00000001" izz="0.00039766" />-->
        </inertial>
    </link>
    <gazebo reference="robot3/link6">
        <kp>1000000.0</kp>
        <kd>100.0</kd>
        <mu1>30.0</mu1>
        <mu2>30.0</mu2>
        <maxVel>1.0</maxVel>
        <minDepth>0.001</minDepth>
        <material>Gazebo/White</material>
        <selfCollide>1</selfCollide>
        <dampingFactor>0.01</dampingFactor>
    </gazebo>
    <!-- Joint 6 -->
    <joint name="robot3/joint6" type="revolute">
        <parent link="robot3/link6" />
        <child link="robot3/link7" />
        <origin rpy="0 0 0" xyz="0.06300 0.04500 0.00000" />
        <axis xyz="0 1 0" />
        <limit effort="100" lower="-1.5707963267948966" upper="1.5707963267948966" velocity="3.03687" />
        <dynamics damping="0.7" />
    </joint>
    <transmission name="robot3/tran6">
        <type>transmission_interface/SimpleTransmission</type>
        <joint name="robot3/joint6">
            <hardwareInterface>hardware_interface/PositionJointInterface</hardwareInterface>
        </joint>
        <actuator name="robot3/motor6">
            <mechanicalReduction>1</mechanicalReduction>
            <hardwareInterface>hardware_interface/PositionJointInterface</hardwareInterface>
        </actuator>
    </transmission>
    <!-- link 6 -->
    <link name="robot3/link7">
        <visual>
            <origin rpy="0 0 0" xyz="-0.034 -0.098 -0.028" />
            <geometry>
                <mesh filename="package://papras_description/meshes/link6_papras.stl" scale="0.001 0.001 0.001" />
            </geometry>
            <material name="grey" />
        </visual>
        <collision>
            <origin rpy="0 0 0" xyz="-0.034 -0.098 -0.028" />
            <geometry>
                <mesh filename="package://papras_description/meshes/link6_papras_simple.stl" scale="0.001 0.001 0.001" />
            </geometry>
        </collision>
        <inertial>
            <origin rpy="0 0 0" xyz="0.06831 -0.04457 0.00000" />
            <!--<origin xyz="-0.05469 0.00043 0.00000" rpy="0 0 0"/>-->
            <mass value="0.43273" />
            <inertia ixx="1.0" ixy="0.0" ixz="0.0" iyy="1.0" iyz="0.0" izz="1.0" />
            <!--<inertia ixx="0.00021512" ixy="0.00001009" ixz="0.00000000" iyy="0.00042827" iyz="0.00000000" izz="0.00051436" />-->
        </inertial>
    </link>
    <gazebo reference="robot3/link7">
        <kp>1000000.0</kp>
        <kd>100.0</kd>
        <mu1>30.0</mu1>
        <mu2>30.0</mu2>
        <maxVel>1.0</maxVel>
        <minDepth>0.001</minDepth>
        <material>Gazebo/White</material>
        <selfCollide>1</selfCollide>
        <dampingFactor>0.01</dampingFactor>
    </gazebo>
    <!-- Joint 7 -->
    <joint name="robot3/joint7" type="revolute">
        <parent link="robot3/link7" />
        <child link="robot3/end_link" />
        <origin rpy="0 0 0" xyz="0.12300 -0.04500 0.00000" />
        <axis xyz="1 0 0" />
        <limit effort="100" lower="-3.141592653589793" upper="3.141592653589793" velocity="3.03687" />
        <dynamics damping="0.7" />
    </joint>
    <transmission name="robot3/tran7">
        <type>transmission_interface/SimpleTransmission</type>
        <joint name="robot3/joint7">
            <hardwareInterface>hardware_interface/PositionJointInterface</hardwareInterface>
        </joint>
        <actuator name="robot3/motor7">
            <mechanicalReduction>1</mechanicalReduction>
            <hardwareInterface>hardware_interface/PositionJointInterface</hardwareInterface>
        </actuator>
    </transmission>
    <!-- end link -->
    <link name="robot3/end_link">
        <visual>
            <origin rpy="0 0 0" xyz="0.0 0.0 0.0" />
            <geometry>
                <mesh filename="package://papras_description/meshes/end_link.stl" scale="0.001 0.001 0.001" />
            </geometry>
            <material name="grey" />
        </visual>
        <collision>
            <origin rpy="0 0 0" xyz="0.0 0.0 0.0" />
            <geometry>
                <mesh filename="package://papras_description/meshes/end_link.stl" scale="0.001 0.001 0.001" />
            </geometry>
        </collision>
        <inertial>
            <origin rpy="0 0 0" xyz="0.00337 0.00000 0.00000" />
            <mass value="0.01919" />
            <inertia ixx="1.0" ixy="0.0" ixz="0.0" iyy="1.0" iyz="0.0" izz="1.0" />
            <!--<inertia ixx="0.00000938" ixy="0.0" ixz="0.0" iyy="0.00000338" iyz="0.0" izz="0.00000635" />-->
        </inertial>
    </link>
    <gazebo reference="robot3/end_link">
        <kp>1000000.0</kp>
        <kd>100.0</kd>
        <mu1>30.0</mu1>
        <mu2>30.0</mu2>
        <maxVel>1.0</maxVel>
        <minDepth>0.001</minDepth>
        <material>Gazebo/White</material>
        <selfCollide>1</selfCollide>
        <dampingFactor>0.01</dampingFactor>
    </gazebo>
    <!-- gripper main fixed joint-->
    <joint name="robot3/end_link_fixed" type="fixed">
        <parent link="robot3/end_link" />
        <child link="robot3/gripper_main_link" />
        <origin rpy="0 -1.5707963267948966 3.141592653589793" xyz="0.006 0.0 0.0" />
    </joint>
    <!-- gripper main link -->
    <link name="robot3/gripper_main_link">
        <collision>
            <origin rpy="0 0 0" xyz="0 0 0" />
            <geometry>
                <mesh filename="package://papras_description/meshes/rh_p12_rn_base.stl" scale="0.001 0.001 0.001" />
            </geometry>
        </collision>
        <visual>
            <origin rpy="0 0 0" xyz="0 0 0" />
            <geometry>
                <mesh filename="package://papras_description/meshes/rh_p12_rn_base.stl" scale="0.001 0.001 0.001" />
            </geometry>
            <material name="grey" />
        </visual>
        <inertial>
            <origin rpy="0 0 0" xyz="0.000 0.000 0.032" />
            <mass value="0.236" />
            <!--<inertia ixx="0.00017" ixy="0.0" ixz="0.0" iyy="0.00011" iyz="0.0" izz="0.00017" />-->
            <inertia ixx="1.0" ixy="0.0" ixz="0.0" iyy="1.0" iyz="0.0" izz="1.0" />
        </inertial>
    </link>
    <gazebo reference="robot3/gripper_main_link">
        <kp>1000000.0</kp>
        <kd>100.0</kd>
        <mu1>30.0</mu1>
        <mu2>30.0</mu2>
        <maxVel>1.0</maxVel>
        <minDepth>0.001</minDepth>
        <material>Gazebo/White</material>
        <selfCollide>1</selfCollide>
        <dampingFactor>0.01</dampingFactor>
    </gazebo>
    <!-- gripper joint -->
    <joint name="robot3/gripper" type="revolute">
        <parent link="robot3/gripper_main_link" />
        <child link="robot3/gripper_link" />
        <origin rpy="0 0 0" xyz="0.0 0.008 0.048" />
        <axis xyz="1 0 0" />
        <limit effort="1000" lower="0.0" upper="1.1" velocity="6.5" />
        <dynamics damping="0.7" />
    </joint>
    <transmission name="robot3/trangripper">
        <type>transmission_interface/SimpleTransmission</type>
        <joint name="robot3/gripper">
            <hardwareInterface>hardware_interface/EffortJointInterface</hardwareInterface>
        </joint>
        <actuator name="robot3/motorgripper">
            <mechanicalReduction>1</mechanicalReduction>
            <hardwareInterface>hardware_interface/EffortJointInterface</hardwareInterface>
        </actuator>
    </transmission>
    <!-- gripper link -->
    <link name="robot3/gripper_link">
        <collision>
            <origin rpy="0 0 0" xyz="0 0 0" />
            <geometry>
                <mesh filename="package://papras_description/meshes/rh_p12_rn_r1.stl" scale="0.001 0.001 0.001" />
            </geometry>
        </collision>
        <visual>
            <origin rpy="0 0 0" xyz="0 0 0" />
            <geometry>
                <mesh filename="package://papras_description/meshes/rh_p12_rn_r1.stl" scale="0.001 0.001 0.001" />
            </geometry>
            <material name="grey" />
        </visual>
        <inertial>
            <origin rpy="0 0 0" xyz="0.000 0.034 0.004" />
            <mass value="0.068" />
            <!--<inertia ixx="0.00004" ixy="0.0" ixz="0.0" iyy="0.00002" iyz="-0.00001" izz="0.00002" />-->
            <inertia ixx="1.0" ixy="0.0" ixz="0.0" iyy="1.0" iyz="0.0" izz="1.0" />
        </inertial>
    </link>
    <gazebo reference="robot3/gripper_link">
        <kp>1000000.0</kp>
        <kd>100.0</kd>
        <mu1>30.0</mu1>
        <mu2>30.0</mu2>
        <maxVel>1.0</maxVel>
        <minDepth>0.001</minDepth>
        <material>Gazebo/White</material>
        <selfCollide>1</selfCollide>
        <dampingFactor>0.01</dampingFactor>
    </gazebo>
    <joint name="robot3/gripper_r2" type="revolute">
        <parent link="robot3/gripper_link" />
        <child link="robot3/gripper_link_r2" />
        <origin rpy="0 0 0" xyz="0.0 0.0493634 0.0285" />
        <axis xyz="-1 0 0" />
        <limit effort="1000" lower="0.0" upper="1.0" velocity="6.5" />
        <dynamics damping="0.7" />
        <mimic joint="robot3/gripper" multiplier="0.9090909090909091" />
    </joint>
    <transmission name="robot3/trangripper_r2">
        <type>transmission_interface/SimpleTransmission</type>
        <joint name="robot3/gripper_r2">
            <hardwareInterface>hardware_interface/EffortJointInterface</hardwareInterface>
        </joint>
        <actuator name="robot3/motorgripper_r2">
            <mechanicalReduction>1</mechanicalReduction>
            <hardwareInterface>hardware_interface/EffortJointInterface</hardwareInterface>
        </actuator>
    </transmission>
    <!-- rh_p12_rn_r2 -->
    <link name="robot3/gripper_link_r2">
        <collision>
            <origin rpy="0 0 0" xyz="0 0 0" />
            <geometry>
                <mesh filename="package://papras_description/meshes/rh_p12_rn_r2.stl" scale="0.001 0.001 0.001" />
            </geometry>
        </collision>
        <visual>
            <origin rpy="0 0 0" xyz="0 0 0" />
            <geometry>
                <mesh filename="package://papras_description/meshes/rh_p12_rn_r2.stl" scale="0.001 0.001 0.001" />
            </geometry>
            <material name="grey" />
        </visual>
        <inertial>
            <origin rpy="0 0 0" xyz="0.000 0.006 0.011" />
            <mass value="0.022" />
            <!--<inertia ixx="0.0" ixy="0.0" ixz="0.0" iyy="0.00001" iyz="0.0" izz="0.0" />-->
            <inertia ixx="1.0" ixy="0.0" ixz="0.0" iyy="1.0" iyz="0.0" izz="1.0" />
        </inertial>
    </link>
    <gazebo reference="robot3/gripper_link_r2">
        <kp>1000000.0</kp>
        <kd>100.0</kd>
        <mu1>30.0</mu1>
        <mu2>30.0</mu2>
        <maxVel>1.0</maxVel>
        <minDepth>0.001</minDepth>
        <material>Gazebo/White</material>
        <selfCollide>1</selfCollide>
        <dampingFactor>0.01</dampingFactor>
    </gazebo>
    <!-- Left Joint 1 -->
    <joint name="robot3/gripper_l1" type="revolute">
        <parent link="robot3/gripper_main_link" />
        <child link="robot3/gripper_link_l1" />
        <origin rpy="0 0 0" xyz="0.0 -0.008 0.048" />
        <axis xyz="-1 0 0" />
        <limit effort="1000" lower="0.0" upper="1.1" velocity="6.5" />
        <dynamics damping="0.7" />
        <mimic joint="robot3/gripper" multiplier="1.0" />
    </joint>
    <transmission name="robot3/trangripper_l1">
        <type>transmission_interface/SimpleTransmission</type>
        <joint name="robot3/gripper_l1">
            <hardwareInterface>hardware_interface/EffortJointInterface</hardwareInterface>
        </joint>
        <actuator name="robot3/motorgripper_l1">
            <mechanicalReduction>1</mechanicalReduction>
            <hardwareInterface>hardware_interface/EffortJointInterface</hardwareInterface>
        </actuator>
    </transmission>
    <!-- rh_p12_rn_l1 -->
    <link name="robot3/gripper_link_l1">
        <collision>
            <origin rpy="0 0 0" xyz="0 0 0" />
            <geometry>
                <mesh filename="package://papras_description/meshes/rh_p12_rn_l1.stl" scale="0.001 0.001 0.001" />
            </geometry>
        </collision>
        <visual>
            <origin rpy="0 0 0" xyz="0 0 0" />
            <geometry>
                <mesh filename="package://papras_description/meshes/rh_p12_rn_l1.stl" scale="0.001 0.001 0.001" />
            </geometry>
            <material name="grey" />
        </visual>
        <inertial>
            <origin rpy="0 0 0" xyz="0.000 -0.034 0.004" />
            <mass value="0.068" />
            <!--<inertia ixx="0.00004" ixy="0.0" ixz="0.0" iyy="0.00002" iyz="0.00001" izz="0.00002" />-->
            <inertia ixx="1.0" ixy="0.0" ixz="0.0" iyy="1.0" iyz="0.0" izz="1.0" />
        </inertial>
    </link>
    <gazebo reference="robot3/gripper_link_l1">
        <kp>1000000.0</kp>
        <kd>100.0</kd>
        <mu1>30.0</mu1>
        <mu2>30.0</mu2>
        <maxVel>1.0</maxVel>
        <minDepth>0.001</minDepth>
        <material>Gazebo/White</material>
        <selfCollide>1</selfCollide>
        <dampingFactor>0.01</dampingFactor>
    </gazebo>
    <!-- Left Joint 2 -->
    <joint name="robot3/gripper_l2" type="revolute">
        <parent link="robot3/gripper_link_l1" />
        <child link="robot3/gripper_link_l2" />
        <origin rpy="0 0 0" xyz="0.0 -0.0493634 0.0285" />
        <axis xyz="1 0 0" />
        <limit effort="1000" lower="0.0" upper="1.0" velocity="6.5" />
        <dynamics damping="0.7" />
        <mimic joint="robot3/gripper" multiplier="0.9090909090909091" />
    </joint>
    <transmission name="robot3/trangripper_l2">
        <type>transmission_interface/SimpleTransmission</type>
        <joint name="robot3/gripper_l2">
            <hardwareInterface>hardware_interface/EffortJointInterface</hardwareInterface>
        </joint>
        <actuator name="robot3/motorgripper_l2">
            <mechanicalReduction>1</mechanicalReduction>
            <hardwareInterface>hardware_interface/EffortJointInterface</hardwareInterface>
        </actuator>
    </transmission>
    <link name="robot3/gripper_link_l2">
        <collision>
            <origin rpy="0 0 0" xyz="0 0 0" />
            <geometry>
                <mesh filename="package://papras_description/meshes/rh_p12_rn_l2.stl" scale="0.001 0.001 0.001" />
            </geometry>
        </collision>
        <visual>
            <origin rpy="0 0 0" xyz="0 0 0" />
            <geometry>
                <mesh filename="package://papras_description/meshes/rh_p12_rn_l2.stl" scale="0.001 0.001 0.001" />
            </geometry>
            <material name="grey" />
        </visual>
        <inertial>
            <origin rpy="0 0 0" xyz="0.000 -0.006 0.011" />
            <mass value="0.022" />
            <!--<inertia ixx="0.0" ixy="0.0" ixz="0.0" iyy="0.00001" iyz="0.0" izz="0.0" />-->
            <inertia ixx="1.0" ixy="0.0" ixz="0.0" iyy="1.0" iyz="0.0" izz="1.0" />
        </inertial>
    </link>
    <!-- gripper main fixed joint-->
    <joint name="robot3/end_effector_joint" type="fixed">
        <parent link="robot3/gripper_main_link" />
        <child link="robot3/end_effector_link" />
        <origin rpy="3.141592653589793 -1.5707963267948966 0" xyz="0.0 0.0 0.135" />
    </joint>
    <!-- End Effector -->
    <link name="robot3/end_effector_link">
        <visual>
            <origin rpy="0 0 0" xyz="0.0 0.0 0.0" />
            <geometry>
                <box size="0.01 0.01 0.01" />
            </geometry>
            <material name="red" />
        </visual>
        <!-- <collision>
        <origin xyz="0.0 0.0 0.0" rpy="0 0 0" />
        <geometry>
          <box size = "0.01 0.01 0.01"/>
        </geometry>
        <material name="red"/>
      </collision> -->
        <inertial>
            <origin rpy="0 0 0" xyz="0.0 0.0 0.0" />
            <mass value="0.001" />
            <inertia ixx="1.0" ixy="0.0" ixz="0.0" iyy="1.0" iyz="0.0" izz="1.0" />
        </inertial>
    </link>
    <gazebo reference="robot3/end_effector_link">
        <material>Gazebo/Red</material>
    </gazebo>
    <gazebo reference="robot3/gripper_main_link" />
    <gazebo>
        <!-- loading plugin: mimic joints works in gazebo now -->
        <plugin filename="libroboticsgroup_upatras_gazebo_mimic_joint_plugin.so" name="gazebo_gripper3_ros_control">
            <joint>robot3/gripper</joint>
            <mimicJoint>robot3/gripper_r2</mimicJoint>
            <multiplier>0.9090909090909091</multiplier>
            <offset>0.0</offset>
        </plugin>
    </gazebo>
    <gazebo>
        <!-- loading plugin: mimic joints works in gazebo now -->
        <plugin filename="libroboticsgroup_upatras_gazebo_mimic_joint_plugin.so" name="gazebo_gripper3_ros_control">
            <joint>robot3/gripper</joint>
            <mimicJoint>robot3/gripper_l1</mimicJoint>
            <multiplier>1.0</multiplier>
            <offset>0.0</offset>
        </plugin>
    </gazebo>
    <gazebo>
        <!-- loading plugin: mimic joints works in gazebo now -->
        <plugin filename="libroboticsgroup_upatras_gazebo_mimic_joint_plugin.so" name="gazebo_gripper3_ros_control">
            <joint>robot3/gripper</joint>
            <mimicJoint>robot3/gripper_l2</mimicJoint>
            <multiplier>0.9090909090909091</multiplier>
            <offset>0.0</offset>
        </plugin>
    </gazebo>
    <gazebo>
        <plugin filename="libgazebo_grasp_fix.so" name="gazebo_grasp_fix">
            <arm>
                <arm_name>robot3</arm_name>
                <palm_link>robot3/end_link</palm_link>
                <gripper_link>robot3/gripper_link_l2</gripper_link>
                <gripper_link>robot3/gripper_link_l1</gripper_link>
                <gripper_link>robot3/gripper_link_r2</gripper_link>
                <gripper_link>robot3/gripper_link</gripper_link>
            </arm>
            <forces_angle_tolerance>100</forces_angle_tolerance>
            <update_rate>4</update_rate>
            <grip_count_threshold>4</grip_count_threshold>
            <max_grip_count>8</max_grip_count>
            <release_tolerance>0.002</release_tolerance>
            <disable_collisions_on_attach>false</disable_collisions_on_attach>
            <contact_topic>__default_topic__</contact_topic>
        </plugin>
    </gazebo>
    <!-- camera link fixed joint -->
    <joint name="robot3/camera_fixed_joint" type="fixed">
        <parent link="robot3/gripper_main_link" />
        <child link="robot3/camera_mount" />
        <origin rpy="0 0 3.141592653589793" xyz="0.030 0.0 0.039" />
    </joint>
    <!-- <origin xyz="0.0592 0.0167 0.04452" rpy="${-0.5*pi} 0 ${-0.5*pi}" /> -->
    <!-- Camera Mount -->
    <link name="robot3/camera_mount">
        <visual>
            <origin rpy="0 0 0" xyz="0 0 0" />
            <geometry>
                <mesh filename="package://papras_description/meshes/camera_mount_far_eye.stl" />
            </geometry>
            <material name="grey" />
        </visual>
        <collision>
            <origin rpy="0 0 0" xyz="0 0 0" />
            <geometry>
                <mesh filename="package://papras_description/meshes/camera_mount_far_eye.stl" />
            </geometry>
        </collision>
        <inertial>
            <origin rpy="0 0 0" xyz="0 0 0" />
            <mass value="0.088" />
            <inertia ixx="1.0" ixy="0.0" ixz="0.0" iyy="1.0" iyz="0.0" izz="1.0" />
        </inertial>
    </link>
    <gazebo reference="robot3/camera_mount">
        <kp>1000000.0</kp>
        <kd>100.0</kd>
        <mu1>30.0</mu1>
        <mu2>30.0</mu2>
        <maxVel>1.0</maxVel>
        <minDepth>0.001</minDepth>
        <material>Gazebo/White</material>
        <selfCollide>1</selfCollide>
        <dampingFactor>0.01</dampingFactor>
    </gazebo>
    <joint name="robot3/camera_mount_link" type="fixed">
        <parent link="robot3/camera_mount" />
        <child link="robot3/camera_link" />
        <origin rpy="0 0 0" xyz="-0.015 0 0" />
    </joint>
    <link name="robot3/camera_link" />
    <joint name="robot3/camera_fixed_plugin_joint" type="fixed">
        <parent link="robot3/camera_link" />
        <child link="robot3/camera_plugin_link" />
        <origin rpy="1.5707963267948966 -1.5707963267948966 0" xyz="0 0 0" />
    </joint>
    <link name="robot3/camera_plugin_link" />
    <gazebo reference="robot3/camera_plugin_link">
        <kp>1000000.0</kp>
        <kd>100.0</kd>
        <mu1>30.0</mu1>
        <mu2>30.0</mu2>
        <maxVel>1.0</maxVel>
        <minDepth>0.001</minDepth>
        <material>Gazebo/White</material>
        <selfCollide>1</selfCollide>
        <dampingFactor>0.01</dampingFactor>
    </gazebo>
    <gazebo reference="robot3/camera_plugin_link">
        <sensor name="robot3/camera_sensor" type="depth">
            <update_rate>30.0</update_rate>
            <camera name="realsense_d435">
                <horizontal_fov>1.20428</horizontal_fov>
                <image>
                    <width>640</width>
                    <height>480</height>
                    <format>R8G8B8</format>
                </image>
                <clip>
                    <near>0.03</near>
                    <far>3</far>
                </clip>
                <noise>
                    <type>gaussian</type>
                    <!-- Noise is sampled independently per pixel on each frame.
                That pixel's noise value is added to each of its color
                channels, which at that point lie in the range [0,1]. -->
                    <mean>0.0</mean>
                    <stddev>0.007</stddev>
                </noise>
            </camera>
            <plugin filename="libgazebo_ros_openni_kinect.so" name="camera_plugin">
                <baseline>0.2</baseline>
                <alwaysOn>true</alwaysOn>
                <!-- Keep this zero, update_rate in the parent <sensor> tag
            will control the frame rate. -->
                <updateRate>0.0</updateRate>
                <cameraName>robot3/camera</cameraName>
                <imageTopicName>color/image_raw</imageTopicName>
                <cameraInfoTopicName>color/camera_info</cameraInfoTopicName>
                <depthImageTopicName>depth/image_raw</depthImageTopicName>
                <depthImageCameraInfoTopicName>depth/camera_info</depthImageCameraInfoTopicName>
                <pointCloudTopicName>depth/points</pointCloudTopicName>
                <frameName>robot3/camera_link</frameName>
                <pointCloudCutoff>0.1</pointCloudCutoff>
                <pointCloudCutoffMax>3.0</pointCloudCutoffMax>
                <distortionK1>0</distortionK1>
                <distortionK2>0</distortionK2>
                <distortionK3>0</distortionK3>
                <distortionT1>0</distortionT1>
                <distortionT2>0</distortionT2>
                <CxPrime>0</CxPrime>
                <Cx>0</Cx>
                <Cy>0</Cy>
                <focalLength>0</focalLength>
                <hackBaseline>0</hackBaseline>
            </plugin>
        </sensor>
    </gazebo>
    <!-- link 1 -->
    <link name="robot4/link1">
        <visual>
            <origin rpy="0 0 0" xyz="0 0 0" />
            <geometry>
                <mesh filename="package://papras_description/meshes/link1.stl" scale="0.001 0.001 0.001" />
            </geometry>
            <material name="grey" />
        </visual>
        <collision>
            <origin rpy="0 0 0" xyz="0 0 0" />
            <geometry>
                <mesh filename="package://papras_description/meshes/link1.stl" scale="0.001 0.001 0.001" />
            </geometry>
        </collision>
        <inertial>
            <origin rpy="0 0 0" xyz="0.00023 0.00000 0.06223" />
            <mass value="0.85644" />
            <!-- <inertia ixx="1.0" ixy="0.0" ixz="0.0" iyy="1.0" iyz="0.0" izz="1.0" /> -->
            <inertia ixx="0.00121064" ixy="0.0" ixz="0.00001100" iyy="0.00120886" iyz="0.0" izz="0.00038103" />
        </inertial>
    </link>
    <gazebo reference="robot4/link1">
        <kp>1000000.0</kp>
        <kd>100.0</kd>
        <mu1>30.0</mu1>
        <mu2>30.0</mu2>
        <maxVel>1.0</maxVel>
        <minDepth>0.001</minDepth>
        <material>Gazebo/White</material>
        <selfCollide>1</selfCollide>
        <dampingFactor>0.01</dampingFactor>
    </gazebo>
    <!-- Joint 1 -->
    <joint name="robot4/joint1" type="revolute">
        <parent link="robot4/link1" />
        <child link="robot4/link2" />
        <origin rpy="0 0 0" xyz="0.0 0.0 0.126" />
        <axis xyz="0 0 1" />
        <limit effort="100" lower="-3.141592653589793" upper="3.141592653589793" velocity="3.03687" />
        <dynamics damping="0.7" />
    </joint>
    <transmission name="robot4/tran1">
        <type>transmission_interface/SimpleTransmission</type>
        <joint name="robot4/joint1">
            <hardwareInterface>hardware_interface/PositionJointInterface</hardwareInterface>
        </joint>
        <actuator name="robot4/motor1">
            <mechanicalReduction>1</mechanicalReduction>
            <hardwareInterface>hardware_interface/PositionJointInterface</hardwareInterface>
        </actuator>
    </transmission>
    <!-- link 2 -->
    <link name="robot4/link2">
        <visual>
            <origin rpy="0 0 0" xyz="0 0 0" />
            <geometry>
                <mesh filename="package://papras_description/meshes/link2.stl" scale="0.001 0.001 0.001" />
            </geometry>
            <material name="grey" />
        </visual>
        <collision>
            <origin rpy="0 0 0" xyz="0 0 0" />
            <geometry>
                <mesh filename="package://papras_description/meshes/link2.stl" scale="0.001 0.001 0.001" />
            </geometry>
        </collision>
        <inertial>
            <origin rpy="0 0 0" xyz="0.00000 0.00080 0.03183" />
            <!--<origin xyz="0.00000 -0.06820 -0.00117" rpy="0 0 0"/>-->
            <mass value="0.94658" />
            <inertia ixx="1.0" ixy="0.0" ixz="0.0" iyy="1.0" iyz="0.0" izz="1.0" />
            <!--<inertia ixx="0.00152547" ixy="0.0" ixz="0.0" iyy="0.00045954" iyz="-0.00001086" izz="0.00151740" />-->
        </inertial>
    </link>
    <gazebo reference="robot4/link2">
        <kp>1000000.0</kp>
        <kd>100.0</kd>
        <mu1>30.0</mu1>
        <mu2>30.0</mu2>
        <maxVel>1.0</maxVel>
        <minDepth>0.001</minDepth>
        <material>Gazebo/White</material>
        <selfCollide>1</selfCollide>
        <dampingFactor>0.01</dampingFactor>
    </gazebo>
    <!-- Joint 2 -->
    <joint name="robot4/joint2" type="revolute">
        <parent link="robot4/link2" />
        <child link="robot4/link3" />
        <origin rpy="1.5707963267948966 -1.5707963267948966 0" xyz="0.0 0.00 0.033" />
        <axis xyz="0 0 1" />
        <limit effort="100" lower="-2.0" upper="2.0" velocity="3.03687" />
        <dynamics damping="0.7" />
    </joint>
    <transmission name="robot4/tran2">
        <type>transmission_interface/SimpleTransmission</type>
        <joint name="robot4/joint2">
            <hardwareInterface>hardware_interface/PositionJointInterface</hardwareInterface>
        </joint>
        <actuator name="robot4/motor2">
            <mechanicalReduction>1</mechanicalReduction>
            <hardwareInterface>hardware_interface/PositionJointInterface</hardwareInterface>
        </actuator>
    </transmission>
    <!-- link 2 -->
    <link name="robot4/link3">
        <visual>
            <origin rpy="0 0 0" xyz="0.0 0.0 0.0" />
            <geometry>
                <mesh filename="package://papras_description/meshes/7dof/link3.stl" />
            </geometry>
            <material name="grey" />
        </visual>
        <collision>
            <origin rpy="0 0 0" xyz="0 0 0" />
            <geometry>
                <mesh filename="package://papras_description/meshes/7dof/link3.stl" />
            </geometry>
        </collision>
        <inertial>
            <origin rpy="0 0 0" xyz="0.00000 0.00080 0.03183" />
            <!--<origin xyz="0.00000 -0.06820 -0.00117" rpy="0 0 0"/>-->
            <mass value="0.49982" />
            <!-- <inertia ixx="1.0" ixy="0.0" ixz="0.0" iyy="1.0" iyz="0.0" izz="1.0" /> -->
            <inertia ixx="0.00078817" ixy="6.3729E-09" ixz="-1.0998E-05" iyy="0.0012133" iyz="-7.0637E-09" izz="0.00073746" />
        </inertial>
    </link>
    <gazebo reference="robot4/link3">
        <kp>1000000.0</kp>
        <kd>100.0</kd>
        <mu1>30.0</mu1>
        <mu2>30.0</mu2>
        <maxVel>1.0</maxVel>
        <minDepth>0.001</minDepth>
        <material>Gazebo/White</material>
        <selfCollide>1</selfCollide>
        <dampingFactor>0.01</dampingFactor>
    </gazebo>
    <!-- Joint 2 -->
    <joint name="robot4/joint3" type="revolute">
        <parent link="robot4/link3" />
        <child link="robot4/link4" />
        <origin rpy="0 -1.5707963267948966 -1.5707963267948966" xyz="0.156382198147594 0 0.000400000000010851" />
        <axis xyz="0 1 0" />
        <limit effort="100" lower="-3.141592653589793" upper="3.141592653589793" velocity="3.03687" />
        <dynamics damping="0.7" />
    </joint>
    <transmission name="robot4/tran3">
        <type>transmission_interface/SimpleTransmission</type>
        <joint name="robot4/joint3">
            <hardwareInterface>hardware_interface/PositionJointInterface</hardwareInterface>
        </joint>
        <actuator name="robot4/motor3">
            <mechanicalReduction>1</mechanicalReduction>
            <hardwareInterface>hardware_interface/PositionJointInterface</hardwareInterface>
        </actuator>
    </transmission>
    <!-- link 2 -->
    <link name="robot4/link4">
        <visual>
            <origin rpy="0 0 0" xyz="0.0 0.0 0.0" />
            <geometry>
                <mesh filename="package://papras_description/meshes/7dof/link4.stl" />
            </geometry>
            <material name="grey" />
        </visual>
        <collision>
            <origin rpy="0 0 0" xyz="0 0 0" />
            <geometry>
                <mesh filename="package://papras_description/meshes/7dof/link4.stl" />
            </geometry>
        </collision>
        <inertial>
            <origin rpy="0 0 0" xyz="-4.86609203880829E-06 0.120506252053841 -0.0279123104678896" />
            <mass value="0.597399042150493" />
            <!-- <inertia ixx="1.0" ixy="0.0" ixz="0.0" iyy="1.0" iyz="0.0" izz="1.0" /> -->
            <inertia ixx="0.0015528567154149" ixy="1.16567414120262E-05" ixz="-2.90009974781987E-06" iyy="0.00077263780701987" iyz="9.95380938833158E-05" izz="0.0018580466481516" />
        </inertial>
    </link>
    <gazebo reference="robot4/link4">
        <kp>1000000.0</kp>
        <kd>100.0</kd>
        <mu1>30.0</mu1>
        <mu2>30.0</mu2>
        <maxVel>1.0</maxVel>
        <minDepth>0.001</minDepth>
        <material>Gazebo/White</material>
        <selfCollide>1</selfCollide>
        <dampingFactor>0.01</dampingFactor>
    </gazebo>
    <!-- Joint 3 -->
    <joint name="robot4/joint4" type="revolute">
        <parent link="robot4/link4" />
        <child link="robot4/link5" />
        <origin rpy="3.141592653589793 -1.5707963267948966 1.5707963267948966" xyz="0.0575 0.10761780185239 0.0300000000000553" />
        <axis xyz="0 1 0" />
        <limit effort="100" lower="-3.141592653589793" upper="1.42" velocity="3.03687" />
        <dynamics damping="0.7" />
    </joint>
    <transmission name="robot4/tran4">
        <type>transmission_interface/SimpleTransmission</type>
        <joint name="robot4/joint4">
            <hardwareInterface>hardware_interface/PositionJointInterface</hardwareInterface>
        </joint>
        <actuator name="robot4/motor4">
            <mechanicalReduction>1</mechanicalReduction>
            <hardwareInterface>hardware_interface/PositionJointInterface</hardwareInterface>
        </actuator>
    </transmission>
    <!-- link 5 -->
    <link name="robot4/link5">
        <visual>
            <origin rpy="0 0 3.14" xyz="0.227 0.0085 -0.024" />
            <geometry>
                <mesh filename="package://papras_description/meshes/link4_papras.stl" scale="0.001 0.001 0.001" />
            </geometry>
            <material name="grey" />
        </visual>
        <collision>
            <origin rpy="0 0 3.14" xyz="0.227 0.0085 -0.024" />
            <geometry>
                <mesh filename="package://papras_description/meshes/link4_papras_simple.stl" scale="0.001 0.001 0.001" />
            </geometry>
        </collision>
        <inertial>
            <origin rpy="0 0 0" xyz="0.12475 -0.05716 0.02979" />
            <!--<origin xyz="-0.07025 0.00034 -0.00021" rpy="0 0 0"/>-->
            <mass value="1.15977" />
            <inertia ixx="1.0" ixy="0.0" ixz="0.0" iyy="1.0" iyz="0.0" izz="1.0" />
            <!--<inertia ixx="0.00096726" ixy="0.00004383" ixz="-0.00002771" iyy="0.00318801" iyz="0.00000627" izz="0.00341484" />-->
        </inertial>
    </link>
    <gazebo reference="robot4/link5">
        <kp>1000000.0</kp>
        <kd>100.0</kd>
        <mu1>30.0</mu1>
        <mu2>30.0</mu2>
        <maxVel>1.0</maxVel>
        <minDepth>0.001</minDepth>
        <material>Gazebo/White</material>
        <selfCollide>1</selfCollide>
        <dampingFactor>0.01</dampingFactor>
    </gazebo>
    <!-- Joint 4 -->
    <joint name="robot4/joint5" type="revolute">
        <parent link="robot4/link5" />
        <child link="robot4/link6" />
        <origin rpy="0 0 0" xyz="0.19500 -0.05750 0.03000" />
        <axis xyz="1 0 0" />
        <limit effort="100" lower="-2.748893571891069" upper="2.748893571891069" velocity="3.03687" />
        <dynamics damping="0.7" />
    </joint>
    <transmission name="robot4/tran5">
        <type>transmission_interface/SimpleTransmission</type>
        <joint name="robot4/joint5">
            <hardwareInterface>hardware_interface/PositionJointInterface</hardwareInterface>
        </joint>
        <actuator name="robot4/motor5">
            <mechanicalReduction>1</mechanicalReduction>
            <hardwareInterface>hardware_interface/PositionJointInterface</hardwareInterface>
        </actuator>
    </transmission>
    <!-- link 6 -->
    <link name="robot4/link6">
        <visual>
            <origin rpy="0 0 0" xyz="0 0 0" />
            <geometry>
                <mesh filename="package://papras_description/meshes/link5.stl" scale="0.001 0.001 0.001" />
            </geometry>
            <material name="grey" />
        </visual>
        <collision>
            <origin rpy="0 0 0" xyz="0 0 0" />
            <geometry>
                <mesh filename="package://papras_description/meshes/link5.stl" scale="0.001 0.001 0.001" />
            </geometry>
        </collision>
        <inertial>
            <origin rpy="0 0 0" xyz="0.05642 -0.00217 0.00002" />
            <!--<origin xyz="-0.00658 -0.04717 0.00002" rpy="0 0 0"/>-->
            <mass value="0.44688" />
            <inertia ixx="1.0" ixy="0.0" ixz="0.0" iyy="1.0" iyz="0.0" izz="1.0" />
            <!--<inertia ixx="0.00030285" ixy="0.00000761" ixz="0.00000031" iyy="0.00022339" iyz="-0.00000001" izz="0.00039766" />-->
        </inertial>
    </link>
    <gazebo reference="robot4/link6">
        <kp>1000000.0</kp>
        <kd>100.0</kd>
        <mu1>30.0</mu1>
        <mu2>30.0</mu2>
        <maxVel>1.0</maxVel>
        <minDepth>0.001</minDepth>
        <material>Gazebo/White</material>
        <selfCollide>1</selfCollide>
        <dampingFactor>0.01</dampingFactor>
    </gazebo>
    <!-- Joint 6 -->
    <joint name="robot4/joint6" type="revolute">
        <parent link="robot4/link6" />
        <child link="robot4/link7" />
        <origin rpy="0 0 0" xyz="0.06300 0.04500 0.00000" />
        <axis xyz="0 1 0" />
        <limit effort="100" lower="-1.5707963267948966" upper="1.5707963267948966" velocity="3.03687" />
        <dynamics damping="0.7" />
    </joint>
    <transmission name="robot4/tran6">
        <type>transmission_interface/SimpleTransmission</type>
        <joint name="robot4/joint6">
            <hardwareInterface>hardware_interface/PositionJointInterface</hardwareInterface>
        </joint>
        <actuator name="robot4/motor6">
            <mechanicalReduction>1</mechanicalReduction>
            <hardwareInterface>hardware_interface/PositionJointInterface</hardwareInterface>
        </actuator>
    </transmission>
    <!-- link 6 -->
    <link name="robot4/link7">
        <visual>
            <origin rpy="0 0 0" xyz="-0.034 -0.098 -0.028" />
            <geometry>
                <mesh filename="package://papras_description/meshes/link6_papras.stl" scale="0.001 0.001 0.001" />
            </geometry>
            <material name="grey" />
        </visual>
        <collision>
            <origin rpy="0 0 0" xyz="-0.034 -0.098 -0.028" />
            <geometry>
                <mesh filename="package://papras_description/meshes/link6_papras_simple.stl" scale="0.001 0.001 0.001" />
            </geometry>
        </collision>
        <inertial>
            <origin rpy="0 0 0" xyz="0.06831 -0.04457 0.00000" />
            <!--<origin xyz="-0.05469 0.00043 0.00000" rpy="0 0 0"/>-->
            <mass value="0.43273" />
            <inertia ixx="1.0" ixy="0.0" ixz="0.0" iyy="1.0" iyz="0.0" izz="1.0" />
            <!--<inertia ixx="0.00021512" ixy="0.00001009" ixz="0.00000000" iyy="0.00042827" iyz="0.00000000" izz="0.00051436" />-->
        </inertial>
    </link>
    <gazebo reference="robot4/link7">
        <kp>1000000.0</kp>
        <kd>100.0</kd>
        <mu1>30.0</mu1>
        <mu2>30.0</mu2>
        <maxVel>1.0</maxVel>
        <minDepth>0.001</minDepth>
        <material>Gazebo/White</material>
        <selfCollide>1</selfCollide>
        <dampingFactor>0.01</dampingFactor>
    </gazebo>
    <!-- Joint 7 -->
    <joint name="robot4/joint7" type="revolute">
        <parent link="robot4/link7" />
        <child link="robot4/end_link" />
        <origin rpy="0 0 0" xyz="0.12300 -0.04500 0.00000" />
        <axis xyz="1 0 0" />
        <limit effort="100" lower="-3.141592653589793" upper="3.141592653589793" velocity="3.03687" />
        <dynamics damping="0.7" />
    </joint>
    <transmission name="robot4/tran7">
        <type>transmission_interface/SimpleTransmission</type>
        <joint name="robot4/joint7">
            <hardwareInterface>hardware_interface/PositionJointInterface</hardwareInterface>
        </joint>
        <actuator name="robot4/motor7">
            <mechanicalReduction>1</mechanicalReduction>
            <hardwareInterface>hardware_interface/PositionJointInterface</hardwareInterface>
        </actuator>
    </transmission>
    <!-- end link -->
    <link name="robot4/end_link">
        <visual>
            <origin rpy="0 0 0" xyz="0.0 0.0 0.0" />
            <geometry>
                <mesh filename="package://papras_description/meshes/end_link.stl" scale="0.001 0.001 0.001" />
            </geometry>
            <material name="grey" />
        </visual>
        <collision>
            <origin rpy="0 0 0" xyz="0.0 0.0 0.0" />
            <geometry>
                <mesh filename="package://papras_description/meshes/end_link.stl" scale="0.001 0.001 0.001" />
            </geometry>
        </collision>
        <inertial>
            <origin rpy="0 0 0" xyz="0.00337 0.00000 0.00000" />
            <mass value="0.01919" />
            <inertia ixx="1.0" ixy="0.0" ixz="0.0" iyy="1.0" iyz="0.0" izz="1.0" />
            <!--<inertia ixx="0.00000938" ixy="0.0" ixz="0.0" iyy="0.00000338" iyz="0.0" izz="0.00000635" />-->
        </inertial>
    </link>
    <gazebo reference="robot4/end_link">
        <kp>1000000.0</kp>
        <kd>100.0</kd>
        <mu1>30.0</mu1>
        <mu2>30.0</mu2>
        <maxVel>1.0</maxVel>
        <minDepth>0.001</minDepth>
        <material>Gazebo/White</material>
        <selfCollide>1</selfCollide>
        <dampingFactor>0.01</dampingFactor>
    </gazebo>
    <!-- gripper main fixed joint-->
    <joint name="robot4/end_link_fixed" type="fixed">
        <parent link="robot4/end_link" />
        <child link="robot4/gripper_main_link" />
        <origin rpy="0 -1.5707963267948966 3.141592653589793" xyz="0.006 0.0 0.0" />
    </joint>
    <!-- gripper main link -->
    <link name="robot4/gripper_main_link">
        <collision>
            <origin rpy="0 0 0" xyz="0 0 0" />
            <geometry>
                <mesh filename="package://papras_description/meshes/rh_p12_rn_base.stl" scale="0.001 0.001 0.001" />
            </geometry>
        </collision>
        <visual>
            <origin rpy="0 0 0" xyz="0 0 0" />
            <geometry>
                <mesh filename="package://papras_description/meshes/rh_p12_rn_base.stl" scale="0.001 0.001 0.001" />
            </geometry>
            <material name="grey" />
        </visual>
        <inertial>
            <origin rpy="0 0 0" xyz="0.000 0.000 0.032" />
            <mass value="0.236" />
            <!--<inertia ixx="0.00017" ixy="0.0" ixz="0.0" iyy="0.00011" iyz="0.0" izz="0.00017" />-->
            <inertia ixx="1.0" ixy="0.0" ixz="0.0" iyy="1.0" iyz="0.0" izz="1.0" />
        </inertial>
    </link>
    <gazebo reference="robot4/gripper_main_link">
        <kp>1000000.0</kp>
        <kd>100.0</kd>
        <mu1>30.0</mu1>
        <mu2>30.0</mu2>
        <maxVel>1.0</maxVel>
        <minDepth>0.001</minDepth>
        <material>Gazebo/White</material>
        <selfCollide>1</selfCollide>
        <dampingFactor>0.01</dampingFactor>
    </gazebo>
    <!-- gripper joint -->
    <joint name="robot4/gripper" type="revolute">
        <parent link="robot4/gripper_main_link" />
        <child link="robot4/gripper_link" />
        <origin rpy="0 0 0" xyz="0.0 0.008 0.048" />
        <axis xyz="1 0 0" />
        <limit effort="1000" lower="0.0" upper="1.1" velocity="6.5" />
        <dynamics damping="0.7" />
    </joint>
    <transmission name="robot4/trangripper">
        <type>transmission_interface/SimpleTransmission</type>
        <joint name="robot4/gripper">
            <hardwareInterface>hardware_interface/EffortJointInterface</hardwareInterface>
        </joint>
        <actuator name="robot4/motorgripper">
            <mechanicalReduction>1</mechanicalReduction>
            <hardwareInterface>hardware_interface/EffortJointInterface</hardwareInterface>
        </actuator>
    </transmission>
    <!-- gripper link -->
    <link name="robot4/gripper_link">
        <collision>
            <origin rpy="0 0 0" xyz="0 0 0" />
            <geometry>
                <mesh filename="package://papras_description/meshes/rh_p12_rn_r1.stl" scale="0.001 0.001 0.001" />
            </geometry>
        </collision>
        <visual>
            <origin rpy="0 0 0" xyz="0 0 0" />
            <geometry>
                <mesh filename="package://papras_description/meshes/rh_p12_rn_r1.stl" scale="0.001 0.001 0.001" />
            </geometry>
            <material name="grey" />
        </visual>
        <inertial>
            <origin rpy="0 0 0" xyz="0.000 0.034 0.004" />
            <mass value="0.068" />
            <!--<inertia ixx="0.00004" ixy="0.0" ixz="0.0" iyy="0.00002" iyz="-0.00001" izz="0.00002" />-->
            <inertia ixx="1.0" ixy="0.0" ixz="0.0" iyy="1.0" iyz="0.0" izz="1.0" />
        </inertial>
    </link>
    <gazebo reference="robot4/gripper_link">
        <kp>1000000.0</kp>
        <kd>100.0</kd>
        <mu1>30.0</mu1>
        <mu2>30.0</mu2>
        <maxVel>1.0</maxVel>
        <minDepth>0.001</minDepth>
        <material>Gazebo/White</material>
        <selfCollide>1</selfCollide>
        <dampingFactor>0.01</dampingFactor>
    </gazebo>
    <joint name="robot4/gripper_r2" type="revolute">
        <parent link="robot4/gripper_link" />
        <child link="robot4/gripper_link_r2" />
        <origin rpy="0 0 0" xyz="0.0 0.0493634 0.0285" />
        <axis xyz="-1 0 0" />
        <limit effort="1000" lower="0.0" upper="1.0" velocity="6.5" />
        <dynamics damping="0.7" />
        <mimic joint="robot4/gripper" multiplier="0.9090909090909091" />
    </joint>
    <transmission name="robot4/trangripper_r2">
        <type>transmission_interface/SimpleTransmission</type>
        <joint name="robot4/gripper_r2">
            <hardwareInterface>hardware_interface/EffortJointInterface</hardwareInterface>
        </joint>
        <actuator name="robot4/motorgripper_r2">
            <mechanicalReduction>1</mechanicalReduction>
            <hardwareInterface>hardware_interface/EffortJointInterface</hardwareInterface>
        </actuator>
    </transmission>
    <!-- rh_p12_rn_r2 -->
    <link name="robot4/gripper_link_r2">
        <collision>
            <origin rpy="0 0 0" xyz="0 0 0" />
            <geometry>
                <mesh filename="package://papras_description/meshes/rh_p12_rn_r2.stl" scale="0.001 0.001 0.001" />
            </geometry>
        </collision>
        <visual>
            <origin rpy="0 0 0" xyz="0 0 0" />
            <geometry>
                <mesh filename="package://papras_description/meshes/rh_p12_rn_r2.stl" scale="0.001 0.001 0.001" />
            </geometry>
            <material name="grey" />
        </visual>
        <inertial>
            <origin rpy="0 0 0" xyz="0.000 0.006 0.011" />
            <mass value="0.022" />
            <!--<inertia ixx="0.0" ixy="0.0" ixz="0.0" iyy="0.00001" iyz="0.0" izz="0.0" />-->
            <inertia ixx="1.0" ixy="0.0" ixz="0.0" iyy="1.0" iyz="0.0" izz="1.0" />
        </inertial>
    </link>
    <gazebo reference="robot4/gripper_link_r2">
        <kp>1000000.0</kp>
        <kd>100.0</kd>
        <mu1>30.0</mu1>
        <mu2>30.0</mu2>
        <maxVel>1.0</maxVel>
        <minDepth>0.001</minDepth>
        <material>Gazebo/White</material>
        <selfCollide>1</selfCollide>
        <dampingFactor>0.01</dampingFactor>
    </gazebo>
    <!-- Left Joint 1 -->
    <joint name="robot4/gripper_l1" type="revolute">
        <parent link="robot4/gripper_main_link" />
        <child link="robot4/gripper_link_l1" />
        <origin rpy="0 0 0" xyz="0.0 -0.008 0.048" />
        <axis xyz="-1 0 0" />
        <limit effort="1000" lower="0.0" upper="1.1" velocity="6.5" />
        <dynamics damping="0.7" />
        <mimic joint="robot4/gripper" multiplier="1.0" />
    </joint>
    <transmission name="robot4/trangripper_l1">
        <type>transmission_interface/SimpleTransmission</type>
        <joint name="robot4/gripper_l1">
            <hardwareInterface>hardware_interface/EffortJointInterface</hardwareInterface>
        </joint>
        <actuator name="robot4/motorgripper_l1">
            <mechanicalReduction>1</mechanicalReduction>
            <hardwareInterface>hardware_interface/EffortJointInterface</hardwareInterface>
        </actuator>
    </transmission>
    <!-- rh_p12_rn_l1 -->
    <link name="robot4/gripper_link_l1">
        <collision>
            <origin rpy="0 0 0" xyz="0 0 0" />
            <geometry>
                <mesh filename="package://papras_description/meshes/rh_p12_rn_l1.stl" scale="0.001 0.001 0.001" />
            </geometry>
        </collision>
        <visual>
            <origin rpy="0 0 0" xyz="0 0 0" />
            <geometry>
                <mesh filename="package://papras_description/meshes/rh_p12_rn_l1.stl" scale="0.001 0.001 0.001" />
            </geometry>
            <material name="grey" />
        </visual>
        <inertial>
            <origin rpy="0 0 0" xyz="0.000 -0.034 0.004" />
            <mass value="0.068" />
            <!--<inertia ixx="0.00004" ixy="0.0" ixz="0.0" iyy="0.00002" iyz="0.00001" izz="0.00002" />-->
            <inertia ixx="1.0" ixy="0.0" ixz="0.0" iyy="1.0" iyz="0.0" izz="1.0" />
        </inertial>
    </link>
    <gazebo reference="robot4/gripper_link_l1">
        <kp>1000000.0</kp>
        <kd>100.0</kd>
        <mu1>30.0</mu1>
        <mu2>30.0</mu2>
        <maxVel>1.0</maxVel>
        <minDepth>0.001</minDepth>
        <material>Gazebo/White</material>
        <selfCollide>1</selfCollide>
        <dampingFactor>0.01</dampingFactor>
    </gazebo>
    <!-- Left Joint 2 -->
    <joint name="robot4/gripper_l2" type="revolute">
        <parent link="robot4/gripper_link_l1" />
        <child link="robot4/gripper_link_l2" />
        <origin rpy="0 0 0" xyz="0.0 -0.0493634 0.0285" />
        <axis xyz="1 0 0" />
        <limit effort="1000" lower="0.0" upper="1.0" velocity="6.5" />
        <dynamics damping="0.7" />
        <mimic joint="robot4/gripper" multiplier="0.9090909090909091" />
    </joint>
    <transmission name="robot4/trangripper_l2">
        <type>transmission_interface/SimpleTransmission</type>
        <joint name="robot4/gripper_l2">
            <hardwareInterface>hardware_interface/EffortJointInterface</hardwareInterface>
        </joint>
        <actuator name="robot4/motorgripper_l2">
            <mechanicalReduction>1</mechanicalReduction>
            <hardwareInterface>hardware_interface/EffortJointInterface</hardwareInterface>
        </actuator>
    </transmission>
    <link name="robot4/gripper_link_l2">
        <collision>
            <origin rpy="0 0 0" xyz="0 0 0" />
            <geometry>
                <mesh filename="package://papras_description/meshes/rh_p12_rn_l2.stl" scale="0.001 0.001 0.001" />
            </geometry>
        </collision>
        <visual>
            <origin rpy="0 0 0" xyz="0 0 0" />
            <geometry>
                <mesh filename="package://papras_description/meshes/rh_p12_rn_l2.stl" scale="0.001 0.001 0.001" />
            </geometry>
            <material name="grey" />
        </visual>
        <inertial>
            <origin rpy="0 0 0" xyz="0.000 -0.006 0.011" />
            <mass value="0.022" />
            <!--<inertia ixx="0.0" ixy="0.0" ixz="0.0" iyy="0.00001" iyz="0.0" izz="0.0" />-->
            <inertia ixx="1.0" ixy="0.0" ixz="0.0" iyy="1.0" iyz="0.0" izz="1.0" />
        </inertial>
    </link>
    <!-- gripper main fixed joint-->
    <joint name="robot4/end_effector_joint" type="fixed">
        <parent link="robot4/gripper_main_link" />
        <child link="robot4/end_effector_link" />
        <origin rpy="3.141592653589793 -1.5707963267948966 0" xyz="0.0 0.0 0.135" />
    </joint>
    <!-- End Effector -->
    <link name="robot4/end_effector_link">
        <visual>
            <origin rpy="0 0 0" xyz="0.0 0.0 0.0" />
            <geometry>
                <box size="0.01 0.01 0.01" />
            </geometry>
            <material name="red" />
        </visual>
        <!-- <collision>
        <origin xyz="0.0 0.0 0.0" rpy="0 0 0" />
        <geometry>
          <box size = "0.01 0.01 0.01"/>
        </geometry>
        <material name="red"/>
      </collision> -->
        <inertial>
            <origin rpy="0 0 0" xyz="0.0 0.0 0.0" />
            <mass value="0.001" />
            <inertia ixx="1.0" ixy="0.0" ixz="0.0" iyy="1.0" iyz="0.0" izz="1.0" />
        </inertial>
    </link>
    <gazebo reference="robot4/end_effector_link">
        <material>Gazebo/Red</material>
    </gazebo>
    <gazebo reference="robot4/gripper_main_link" />
    <gazebo>
        <!-- loading plugin: mimic joints works in gazebo now -->
        <plugin filename="libroboticsgroup_upatras_gazebo_mimic_joint_plugin.so" name="gazebo_gripper4_ros_control">
            <joint>robot4/gripper</joint>
            <mimicJoint>robot4/gripper_r2</mimicJoint>
            <multiplier>0.9090909090909091</multiplier>
            <offset>0.0</offset>
        </plugin>
    </gazebo>
    <gazebo>
        <!-- loading plugin: mimic joints works in gazebo now -->
        <plugin filename="libroboticsgroup_upatras_gazebo_mimic_joint_plugin.so" name="gazebo_gripper4_ros_control">
            <joint>robot4/gripper</joint>
            <mimicJoint>robot4/gripper_l1</mimicJoint>
            <multiplier>1.0</multiplier>
            <offset>0.0</offset>
        </plugin>
    </gazebo>
    <gazebo>
        <!-- loading plugin: mimic joints works in gazebo now -->
        <plugin filename="libroboticsgroup_upatras_gazebo_mimic_joint_plugin.so" name="gazebo_gripper4_ros_control">
            <joint>robot4/gripper</joint>
            <mimicJoint>robot4/gripper_l2</mimicJoint>
            <multiplier>0.9090909090909091</multiplier>
            <offset>0.0</offset>
        </plugin>
    </gazebo>
    <gazebo>
        <plugin filename="libgazebo_grasp_fix.so" name="gazebo_grasp_fix">
            <arm>
                <arm_name>robot4</arm_name>
                <palm_link>robot4/end_link</palm_link>
                <gripper_link>robot4/gripper_link_l2</gripper_link>
                <gripper_link>robot4/gripper_link_l1</gripper_link>
                <gripper_link>robot4/gripper_link_r2</gripper_link>
                <gripper_link>robot4/gripper_link</gripper_link>
            </arm>
            <forces_angle_tolerance>100</forces_angle_tolerance>
            <update_rate>4</update_rate>
            <grip_count_threshold>4</grip_count_threshold>
            <max_grip_count>8</max_grip_count>
            <release_tolerance>0.002</release_tolerance>
            <disable_collisions_on_attach>false</disable_collisions_on_attach>
            <contact_topic>__default_topic__</contact_topic>
        </plugin>
    </gazebo>
    <!-- camera link fixed joint -->
    <joint name="robot4/camera_fixed_joint" type="fixed">
        <parent link="robot4/gripper_main_link" />
        <child link="robot4/camera_mount" />
        <origin rpy="0 0 3.141592653589793" xyz="0.030 0.0 0.039" />
    </joint>
    <!-- <origin xyz="0.0592 0.0167 0.04452" rpy="${-0.5*pi} 0 ${-0.5*pi}" /> -->
    <!-- Camera Mount -->
    <link name="robot4/camera_mount">
        <visual>
            <origin rpy="0 0 0" xyz="0 0 0" />
            <geometry>
                <mesh filename="package://papras_description/meshes/camera_mount_far_eye.stl" />
            </geometry>
            <material name="grey" />
        </visual>
        <collision>
            <origin rpy="0 0 0" xyz="0 0 0" />
            <geometry>
                <mesh filename="package://papras_description/meshes/camera_mount_far_eye.stl" />
            </geometry>
        </collision>
        <inertial>
            <origin rpy="0 0 0" xyz="0 0 0" />
            <mass value="0.088" />
            <inertia ixx="1.0" ixy="0.0" ixz="0.0" iyy="1.0" iyz="0.0" izz="1.0" />
        </inertial>
    </link>
    <gazebo reference="robot4/camera_mount">
        <kp>1000000.0</kp>
        <kd>100.0</kd>
        <mu1>30.0</mu1>
        <mu2>30.0</mu2>
        <maxVel>1.0</maxVel>
        <minDepth>0.001</minDepth>
        <material>Gazebo/White</material>
        <selfCollide>1</selfCollide>
        <dampingFactor>0.01</dampingFactor>
    </gazebo>
    <joint name="robot4/camera_mount_link" type="fixed">
        <parent link="robot4/camera_mount" />
        <child link="robot4/camera_link" />
        <origin rpy="0 0 0" xyz="-0.015 0 0" />
    </joint>
    <link name="robot4/camera_link" />
    <joint name="robot4/camera_fixed_plugin_joint" type="fixed">
        <parent link="robot4/camera_link" />
        <child link="robot4/camera_plugin_link" />
        <origin rpy="1.5707963267948966 -1.5707963267948966 0" xyz="0 0 0" />
    </joint>
    <link name="robot4/camera_plugin_link" />
    <gazebo reference="robot4/camera_plugin_link">
        <kp>1000000.0</kp>
        <kd>100.0</kd>
        <mu1>30.0</mu1>
        <mu2>30.0</mu2>
        <maxVel>1.0</maxVel>
        <minDepth>0.001</minDepth>
        <material>Gazebo/White</material>
        <selfCollide>1</selfCollide>
        <dampingFactor>0.01</dampingFactor>
    </gazebo>
    <gazebo reference="robot4/camera_plugin_link">
        <sensor name="robot4/camera_sensor" type="depth">
            <update_rate>30.0</update_rate>
            <camera name="realsense_d435">
                <horizontal_fov>1.20428</horizontal_fov>
                <image>
                    <width>640</width>
                    <height>480</height>
                    <format>R8G8B8</format>
                </image>
                <clip>
                    <near>0.03</near>
                    <far>3</far>
                </clip>
                <noise>
                    <type>gaussian</type>
                    <!-- Noise is sampled independently per pixel on each frame.
                That pixel's noise value is added to each of its color
                channels, which at that point lie in the range [0,1]. -->
                    <mean>0.0</mean>
                    <stddev>0.007</stddev>
                </noise>
            </camera>
            <plugin filename="libgazebo_ros_openni_kinect.so" name="camera_plugin">
                <baseline>0.2</baseline>
                <alwaysOn>true</alwaysOn>
                <!-- Keep this zero, update_rate in the parent <sensor> tag
            will control the frame rate. -->
                <updateRate>0.0</updateRate>
                <cameraName>robot4/camera</cameraName>
                <imageTopicName>color/image_raw</imageTopicName>
                <cameraInfoTopicName>color/camera_info</cameraInfoTopicName>
                <depthImageTopicName>depth/image_raw</depthImageTopicName>
                <depthImageCameraInfoTopicName>depth/camera_info</depthImageCameraInfoTopicName>
                <pointCloudTopicName>depth/points</pointCloudTopicName>
                <frameName>robot4/camera_link</frameName>
                <pointCloudCutoff>0.1</pointCloudCutoff>
                <pointCloudCutoffMax>3.0</pointCloudCutoffMax>
                <distortionK1>0</distortionK1>
                <distortionK2>0</distortionK2>
                <distortionK3>0</distortionK3>
                <distortionT1>0</distortionT1>
                <distortionT2>0</distortionT2>
                <CxPrime>0</CxPrime>
                <Cx>0</Cx>
                <Cy>0</Cy>
                <focalLength>0</focalLength>
                <hackBaseline>0</hackBaseline>
            </plugin>
        </sensor>
    </gazebo>
</robot>

